Workbook

Sheet Instructions
A1: ⬡ DAWA INTEL — MASTER PHARMACY TRACKER | v2 | Smart Pharmacy. Smarter Decisions.
A2: Nakuru County, Kenya | One Google Form · One Spreadsheet · Multiple Pharmacies
A4: TABS IN THIS WORKBOOK
A5: 📄 Instructions | D5: This tab — column guide, formula legend, key rules. Read first.
A6: 📄 Mary Wanjiku Pharmacy | D6: Sample pharmacy tab. Duplicate this tab for every new pharmacy you onboard.
A7: 📄 Batch Register | D7: All batches with expiry dates. One row per received batch, any pharmacy.
A8: 📄 Overview Dashboard | D8: Live summary across all pharmacies. Check every Sunday evening.
A9: 📄 Form Responses 1 | D9: Auto-populated by Google Form. DO NOT edit this tab manually.
A11: COLUMN GUIDE — MARY WANJIKU PHARMACY TAB
A12: Col | B12: Header | C12: Type | D12: Description
A13: A | B13: Drug Name | C13: YELLOW | D13: Enter once on setup. Generic name + strength + form only. Must match Form dropdown exactly.
A14: B | B14: Unit | C14: YELLOW | D14: Enter once. tabs / caps / bottles / vials / sachets / inhalers / etc.
A15: C | B15: Current Stock ★ | C15: GREEN | D15: AUTO from Form entries + col M opening stock. Never type here. Updates every time Form is submitted.
A16: D | B16: Weekly Disp. Avg | C16: GREEN | D16: AUTO — SUMPRODUCT of last 90 days dispensed entries from Form Responses, divided by weeks.
A17: E | B17: Daily Avg | C17: GREEN | D17: AUTO — col D ÷ 7. Used internally by Days Remaining formula.
A18: F | B18: Days Remaining ★ | C18: GREEN | D18: AUTO — Current Stock ÷ Daily Avg. THE KEY NUMBER. Scan this every Sunday.
A19: G | B19: Regional Avg (Days) | C19: YELLOW | D19: Manual benchmark. Nakuru averages pre-loaded. Update monthly from Overview Dashboard once 3+ pharmacies enrolled.
A20: H | B20: Stock Status | C20: GREEN | D20: AUTO — STOCKOUT (0d) / CRITICAL (≤7d) / LOW (≤14d) / ADEQUATE (≤30d) / GOOD (>30d).
A21: I | B21: Nearest Expiry | C21: GREEN | D21: AUTO — pulls nearest future expiry date from Batch Register for this drug. Update Batch Register when stock received.
A22: J | B22: Days to Expiry | C22: GREEN | D22: AUTO — INT(I - TODAY()). Positive = days remaining. Negative = already expired.
A23: K | B23: Expiry Status | C23: GREEN | D23: AUTO — EXPIRED / EXPIRES SOON (≤30d) / EXPIRING 60D (≤60d) / OK.
... A25: M | B25: Opening Stock | C25: YELLOW | D25: Enter ONCE on Day 1 (physical count). Then LOCK this column. Never change unless you do a full recount.
A27: KEY RULES
A28: 1. YELLOW cells = you enter data manually. GREEN cells = auto-formula — never type in a green cell.
A29: 2. Column A (Drug Name) MUST match exactly what is in the Google Form drug dropdown. One typo = formula finds nothing.
A30: 3. Column M (Opening Stock): enter the physical count from Day 1. Lock the column. Only change after a full physical recount.
A31: 4. Batch Register: add one row every time you receive a new batch of any drug. This drives the automatic expiry tracking.
A32: 5. One Google Form for all pharmacies. One Form Responses tab. Each pharmacy tab filters by its own name in column B of the form.
A33: 6. To add a pharmacy: right-click the Mary Wanjiku tab → Duplicate → Rename → update col A drugs and col M opening stocks.
A34: 7. Column L (Alert Flag) is your Sunday scan. Any 'ACTION NEEDED' row goes straight into Monday's WhatsApp report.
A35: 8. Regional Avg (col G): update monthly once you have 3+ pharmacies. Pre-loaded Nakuru benchmarks are reasonable starting values.

Sheet Mary Wanjiku Pharmacy
A1: ⬡ DAWA INTEL — Mary Wanjiku Pharmacy | Weekly Stock Intelligence Tracker
A2: 🟡 YELLOW = Enter manually | E2: 🟢 GREEN = Auto-formula (never type here) | L2: ★ = Key columns to check
A3: Drug Name | B3: Unit | C3: Current Stock ★ | D3: Weekly Disp. Avg | E3: Daily Avg | F3: Days Remaining ★ | G3: Regional Avg (Days) | H3: Stock Status | I3: Nearest Expiry (Auto) | J3: Days to Expiry | K3: Expiry Status | L3: Alert Flag ★ SCAN SUN | M3: Opening Stock (Day 1)
A4: Metformin 500mg tabs | B4: tabs | C4: =IFERROR(M4+SUMPRODUCT(('Form Responses 1'!$B$2:$B$500="Mary Wanjiku Pharmacy")*('Form Responses 1'!$E$2:$E$500=A4)*('Form Responses 1'!$F$2:$F$500="Received")*'Form Responses 1'!$G$2:$G$500)-SUMPRODUCT(('Form Responses 1'!$B$2:$B$500="Mary Wanjiku Pharmacy")*('Form Responses 1'!$E$2:$E$500=A4)*('Form Responses 1'!$F$2:$F$500="Dispensed")*'Form Responses 1'!$G$2:$G$500)-SUMPRODUCT(('Form Responses 1'!$B$2:$B$500="Mary Wanjiku Pharmacy")*('Form Responses 1'!$E$2:$E$500=A4)*('Form Responses 1'!$F$2:$F$500="Expired")*'Form Responses 1'!$G$2:$G$500)+SUMPRODUCT(('Form Responses 1'!$B$2:$B$500="Mary Wanjiku Pharmacy")*('Form Responses 1'!$E$2:$E$500=A4)*('Form Responses 1'!$F$2:$F$500="Returned")*'Form Responses 1'!$G$2:$G$500),0) | D4: =IFERROR(SUMPRODUCT(('Form Responses 1'!$B$2:$B$500="Mary Wanjiku Pharmacy")*('Form Responses 1'!$E$2:$E$500=A4)*('Form Responses 1'!$F$2:$F$500="Dispensed")*(DATEVALUE(TEXT('Form Responses 1'!$C$2:$C$500,"YYYY-MM-DD"))>=(TODAY()-90))*'Form Responses 1'!$G$2:$G$500)/MAX(1,SUMPRODUCT(('Form Responses 1'!$B$2:$B$500="Mary Wanjiku Pharmacy")*('Form Responses 1'!$E$2:$E$500=A4)*('Form Responses 1'!$F$2:$F$500="Dispensed")*(DATEVALUE(TEXT('Form Responses 1'!$C$2:$C$500,"YYYY-MM-DD"))>=(TODAY()-90)))/7*7)*7,0) | E4: =IFERROR(D4/7,0) | F4: =IFERROR(IF(E4=0,IF(C4>0,999,0),ROUND(C4/E4,0)),0) | G4: 28 | H4: =IF(F4<=0,"STOCKOUT",IF(F4<=7,"CRITICAL",IF(F4<=14,"LOW",IF(F4<=30,"ADEQUATE","GOOD")))) | I4: =IFERROR(TEXT(MINIFS('Batch Register'!$F:$F,'Batch Register'!$A:$A,"Mary Wanjiku Pharmacy",'Batch Register'!$B:$B,A4,'Batch Register'!$G:$G,"Active",'Batch Register'!$F:$F,">"&TODAY()),"YYYY-MM-DD"),"No active batch") | J4: =IF(OR(I4="",I4="No active batch"),"",INT(DATEVALUE(I4)-TODAY())) | K4: =IF(OR(I4="",I4="No active batch"),"OK",IF(J4<=0,"EXPIRED",IF(J4<=30,"EXPIRES SOON",IF(J4<=60,"EXPIRING 60D","OK")))) | L4: =IF(OR(H4="STOCKOUT",H4="CRITICAL",K4="EXPIRED",K4="EXPIRES SOON"),"ACTION NEEDED",IF(OR(H4="LOW",K4="EXPIRING 60D"),"MONITOR","OK")) | M4: 500
A5: Paracetamol 500mg tabs | B5: tabs | C5: =IFERROR(M5+SUMPRODUCT(('Form Responses 1'!$B$2:$B$500="Mary Wanjiku Pharmacy")*('Form Responses 1'!$E$2:$E$500=A5)*('Form Responses 1'!$F$2:$F$500="Received")*'Form Responses 1'!$G$2:$G$500)-SUMPRODUCT(('Form Responses 1'!$B$2:$B$500="Mary Wanjiku Pharmacy")*('Form Responses 1'!$E$2:$E$500=A5)*('Form Responses 1'!$F$2:$F$500="Dispensed")*'Form Responses 1'!$G$2:$G$500)-SUMPRODUCT(('Form Responses 1'!$B$2:$B$500="Mary Wanjiku Pharmacy")*('Form Responses 1'!$E$2:$E$500=A5)*('Form Responses 1'!$F$2:$F$500="Expired")*'Form Responses 1'!$G$2:$G$500)+SUMPRODUCT(('Form Responses 1'!$B$2:$B$500="Mary Wanjiku Pharmacy")*('Form Responses 1'!$E$2:$E$500=A5)*('Form Responses 1'!$F$2:$F$500="Returned")*'Form Responses 1'!$G$2:$G$500),0) | D5: =IFERROR(SUMPRODUCT(('Form Responses 1'!$B$2:$B$500="Mary Wanjiku Pharmacy")*('Form Responses 1'!$E$2:$E$500=A5)*('Form Responses 1'!$F$2:$F$500="Dispensed")*(DATEVALUE(TEXT('Form Responses 1'!$C$2:$C$500,"YYYY-MM-DD"))>=(TODAY()-90))*'Form Responses 1'!$G$2:$G$500)/MAX(1,SUMPRODUCT(('Form Responses 1'!$B$2:$B$500="Mary Wanjiku Pharmacy")*('Form Responses 1'!$E$2:$E$500=A5)*('Form Responses 1'!$F$2:$F$500="Dispensed")*(DATEVALUE(TEXT('Form Responses 1'!$C$2:$C$500,"YYYY-MM-DD"))>=(TODAY()-90)))/7*7)*7,0) | E5: =IFERROR(D5/7,0) | F5: =IFERROR(IF(E5=0,IF(C5>0,999,0),ROUND(C5/E5,0)),0) | G5: 14 | H5: =IF(F5<=0,"STOCKOUT",IF(F5<=7,"CRITICAL",IF(F5<=14,"LOW",IF(F5<=30,"ADEQUATE","GOOD")))) | I5: =IFERROR(TEXT(MINIFS('Batch Register'!$F:$F,'Batch Register'!$A:$A,"Mary Wanjiku Pharmacy",'Batch Register'!$B:$B,A5,'Batch Register'!$G:$G,"Active",'Batch Register'!$F:$F,">"&TODAY()),"YYYY-MM-DD"),"No active batch") | J5: =IF(OR(I5="",I5="No active batch"),"",INT(DATEVALUE(I5)-TODAY())) | K5: =IF(OR(I5="",I5="No active batch"),"OK",IF(J5<=0,"EXPIRED",IF(J5<=30,"EXPIRES SOON",IF(J5<=60,"EXPIRING 60D","OK")))) | L5: =IF(OR(H5="STOCKOUT",H5="CRITICAL",K5="EXPIRED",K5="EXPIRES SOON"),"ACTION NEEDED",IF(OR(H5="LOW",K5="EXPIRING 60D"),"MONITOR","OK")) | M5: 800
A6: Amoxicillin 250mg caps | B6: caps | C6: =IFERROR(M6+SUMPRODUCT(('Form Responses 1'!$B$2:$B$500="Mary Wanjiku Pharmacy")*('Form Responses 1'!$E$2:$E$500=A6)*('Form Responses 1'!$F$2:$F$500="Received")*'Form Responses 1'!$G$2:$G$500)-SUMPRODUCT(('Form Responses 1'!$B$2:$B$500="Mary Wanjiku Pharmacy")*('Form Responses 1'!$E$2:$E$500=A6)*('Form Responses 1'!$F$2:$F$500="Dispensed")*'Form Responses 1'!$G$2:$G$500)-SUMPRODUCT(('Form Responses 1'!$B$2:$B$500="Mary Wanjiku Pharmacy")*('Form Responses 1'!$E$2:$E$500=A6)*('Form Responses 1'!$F$2:$F$500="Expired")*'Form Responses 1'!$G$2:$G$500)+SUMPRODUCT(('Form Responses 1'!$B$2:$B$500="Mary Wanjiku Pharmacy")*('Form Responses 1'!$E$2:$E$500=A6)*('Form Responses 1'!$F$2:$F$500="Returned")*'Form Responses 1'!$G$2:$G$500),0) | D6: =IFERROR(SUMPRODUCT(('Form Responses 1'!$B$2:$B$500="Mary Wanjiku Pharmacy")*('Form Responses 1'!$E$2:$E$500=A6)*('Form Responses 1'!$F$2:$F$500="Dispensed")*(DATEVALUE(TEXT('Form Responses 1'!$C$2:$C$500,"YYYY-MM-DD"))>=(TODAY()-90))*'Form Responses 1'!$G$2:$G$500)/MAX(1,SUMPRODUCT(('Form Responses 1'!$B$2:$B$500="Mary Wanjiku Pharmacy")*('Form Responses 1'!$E$2:$E$500=A6)*('Form Responses 1'!$F$2:$F$500="Dispensed")*(DATEVALUE(TEXT('Form Responses 1'!$C$2:$C$500,"YYYY-MM-DD"))>=(TODAY()-90)))/7*7)*7,0) | E6: =IFERROR(D6/7,0) | F6: =IFERROR(IF(E6=0,IF(C6>0,999,0),ROUND(C6/E6,0)),0) | G6: 18 | H6: =IF(F6<=0,"STOCKOUT",IF(F6<=7,"CRITICAL",IF(F6<=14,"LOW",IF(F6<=30,"ADEQUATE","GOOD")))) | I6: =IFERROR(TEXT(MINIFS('Batch Register'!$F:$F,'Batch Register'!$A:$A,"Mary Wanjiku Pharmacy",'Batch Register'!$B:$B,A6,'Batch Register'!$G:$G,"Active",'Batch Register'!$F:$F,">"&TODAY()),"YYYY-MM-DD"),"No active batch") | J6: =IF(OR(I6="",I6="No active batch"),"",INT(DATEVALUE(I6)-TODAY())) | K6: =IF(OR(I6="",I6="No active batch"),"OK",IF(J6<=0,"EXPIRED",IF(J6<=30,"EXPIRES SOON",IF(J6<=60,"EXPIRING 60D","OK")))) | L6: =IF(OR(H6="STOCKOUT",H6="CRITICAL",K6="EXPIRED",K6="EXPIRES SOON"),"ACTION NEEDED",IF(OR(H6="LOW",K6="EXPIRING 60D"),"MONITOR","OK")) | M6: 400
A7: Amlodipine 5mg tabs | B7: tabs | C7: =IFERROR(M7+SUMPRODUCT(('Form Responses 1'!$B$2:$B$500="Mary Wanjiku Pharmacy")*('Form Responses 1'!$E$2:$E$500=A7)*('Form Responses 1'!$F$2:$F$500="Received")*'Form Responses 1'!$G$2:$G$500)-SUMPRODUCT(('Form Responses 1'!$B$2:$B$500="Mary Wanjiku Pharmacy")*('Form Responses 1'!$E$2:$E$500=A7)*('Form Responses 1'!$F$2:$F$500="Dispensed")*'Form Responses 1'!$G$2:$G$500)-SUMPRODUCT(('Form Responses 1'!$B$2:$B$500="Mary Wanjiku Pharmacy")*('Form Responses 1'!$E$2:$E$500=A7)*('Form Responses 1'!$F$2:$F$500="Expired")*'Form Responses 1'!$G$2:$G$500)+SUMPRODUCT(('Form Responses 1'!$B$2:$B$500="Mary Wanjiku Pharmacy")*('Form Responses 1'!$E$2:$E$500=A7)*('Form Responses 1'!$F$2:$F$500="Returned")*'Form Responses 1'!$G$2:$G$500),0) | D7: =IFERROR(SUMPRODUCT(('Form Responses 1'!$B$2:$B$500="Mary Wanjiku Pharmacy")*('Form Responses 1'!$E$2:$E$500=A7)*('Form Responses 1'!$F$2:$F$500="Dispensed")*(DATEVALUE(TEXT('Form Responses 1'!$C$2:$C$500,"YYYY-MM-DD"))>=(TODAY()-90))*'Form Responses 1'!$G$2:$G$500)/MAX(1,SUMPRODUCT(('Form Responses 1'!$B$2:$B$500="Mary Wanjiku Pharmacy")*('Form Responses 1'!$E$2:$E$500=A7)*('Form Responses 1'!$F$2:$F$500="Dispensed")*(DATEVALUE(TEXT('Form Responses 1'!$C$2:$C$500,"YYYY-MM-DD"))>=(TODAY()-90)))/7*7)*7,0) | E7: =IFERROR(D7/7,0) | F7: =IFERROR(IF(E7=0,IF(C7>0,999,0),ROUND(C7/E7,0)),0) | G7: 26 | H7: =IF(F7<=0,"STOCKOUT",IF(F7<=7,"CRITICAL",IF(F7<=14,"LOW",IF(F7<=30,"ADEQUATE","GOOD")))) | I7: =IFERROR(TEXT(MINIFS('Batch Register'!$F:$F,'Batch Register'!$A:$A,"Mary Wanjiku Pharmacy",'Batch Register'!$B:$B,A7,'Batch Register'!$G:$G,"Active",'Batch Register'!$F:$F,">"&TODAY()),"YYYY-MM-DD"),"No active batch") | J7: =IF(OR(I7="",I7="No active batch"),"",INT(DATEVALUE(I7)-TODAY())) | K7: =IF(OR(I7="",I7="No active batch"),"OK",IF(J7<=0,"EXPIRED",IF(J7<=30,"EXPIRES SOON",IF(J7<=60,"EXPIRING 60D","OK")))) | L7: =IF(OR(H7="STOCKOUT",H7="CRITICAL",K7="EXPIRED",K7="EXPIRES SOON"),"ACTION NEEDED",IF(OR(H7="LOW",K7="EXPIRING 60D"),"MONITOR","OK")) | M7: 300
A8: Ibuprofen 400mg tabs | B8: tabs | C8: =IFERROR(M8+SUMPRODUCT(('Form Responses 1'!$B$2:$B$500="Mary Wanjiku Pharmacy")*('Form Responses 1'!$E$2:$E$500=A8)*('Form Responses 1'!$F$2:$F$500="Received")*'Form Responses 1'!$G$2:$G$500)-SUMPRODUCT(('Form Responses 1'!$B$2:$B$500="Mary Wanjiku Pharmacy")*('Form Responses 1'!$E$2:$E$500=A8)*('Form Responses 1'!$F$2:$F$500="Dispensed")*'Form Responses 1'!$G$2:$G$500)-SUMPRODUCT(('Form Responses 1'!$B$2:$B$500="Mary Wanjiku Pharmacy")*('Form Responses 1'!$E$2:$E$500=A8)*('Form Responses 1'!$F$2:$F$500="Expired")*'Form Responses 1'!$G$2:$G$500)+SUMPRODUCT(('Form Responses 1'!$B$2:$B$500="Mary Wanjiku Pharmacy")*('Form Responses 1'!$E$2:$E$500=A8)*('Form Responses 1'!$F$2:$F$500="Returned")*'Form Responses 1'!$G$2:$G$500),0) | D8: =IFERROR(SUMPRODUCT(('Form Responses 1'!$B$2:$B$500="Mary Wanjiku Pharmacy")*('Form Responses 1'!$E$2:$E$500=A8)*('Form Responses 1'!$F$2:$F$500="Dispensed")*(DATEVALUE(TEXT('Form Responses 1'!$C$2:$C$500,"YYYY-MM-DD"))>=(TODAY()-90))*'Form Responses 1'!$G$2:$G$500)/MAX(1,SUMPRODUCT(('Form Responses 1'!$B$2:$B$500="Mary Wanjiku Pharmacy")*('Form Responses 1'!$E$2:$E$500=A8)*('Form Responses 1'!$F$2:$F$500="Dispensed")*(DATEVALUE(TEXT('Form Responses 1'!$C$2:$C$500,"YYYY-MM-DD"))>=(TODAY()-90)))/7*7)*7,0) | E8: =IFERROR(D8/7,0) | F8: =IFERROR(IF(E8=0,IF(C8>0,999,0),ROUND(C8/E8,0)),0) | G8: 12 | H8: =IF(F8<=0,"STOCKOUT",IF(F8<=7,"CRITICAL",IF(F8<=14,"LOW",IF(F8<=30,"ADEQUATE","GOOD")))) | I8: =IFERROR(TEXT(MINIFS('Batch Register'!$F:$F,'Batch Register'!$A:$A,"Mary Wanjiku Pharmacy",'Batch Register'!$B:$B,A8,'Batch Register'!$G:$G,"Active",'Batch Register'!$F:$F,">"&TODAY()),"YYYY-MM-DD"),"No active batch") | J8: =IF(OR(I8="",I8="No active batch"),"",INT(DATEVALUE(I8)-TODAY())) | K8: =IF(OR(I8="",I8="No active batch"),"OK",IF(J8<=0,"EXPIRED",IF(J8<=30,"EXPIRES SOON",IF(J8<=60,"EXPIRING 60D","OK")))) | L8: =IF(OR(H8="STOCKOUT",H8="CRITICAL",K8="EXPIRED",K8="EXPIRES SOON"),"ACTION NEEDED",IF(OR(H8="LOW",K8="EXPIRING 60D"),"MONITOR","OK")) | M8: 150
A9: ORS Sachet | B9: sachets | C9: =IFERROR(M9+SUMPRODUCT(('Form Responses 1'!$B$2:$B$500="Mary Wanjiku Pharmacy")*('Form Responses 1'!$E$2:$E$500=A9)*('Form Responses 1'!$F$2:$F$500="Received")*'Form Responses 1'!$G$2:$G$500)-SUMPRODUCT(('Form Responses 1'!$B$2:$B$500="Mary Wanjiku Pharmacy")*('Form Responses 1'!$E$2:$E$500=A9)*('Form Responses 1'!$F$2:$F$500="Dispensed")*'Form Responses 1'!$G$2:$G$500)-SUMPRODUCT(('Form Responses 1'!$B$2:$B$500="Mary Wanjiku Pharmacy")*('Form Responses 1'!$E$2:$E$500=A9)*('Form Responses 1'!$F$2:$F$500="Expired")*'Form Responses 1'!$G$2:$G$500)+SUMPRODUCT(('Form Responses 1'!$B$2:$B$500="Mary Wanjiku Pharmacy")*('Form Responses 1'!$E$2:$E$500=A9)*('Form Responses 1'!$F$2:$F$500="Returned")*'Form Responses 1'!$G$2:$G$500),0) | D9: =IFERROR(SUMPRODUCT(('Form Responses 1'!$B$2:$B$500="Mary Wanjiku Pharmacy")*('Form Responses 1'!$E$2:$E$500=A9)*('Form Responses 1'!$F$2:$F$500="Dispensed")*(DATEVALUE(TEXT('Form Responses 1'!$C$2:$C$500,"YYYY-MM-DD"))>=(TODAY()-90))*'Form Responses 1'!$G$2:$G$500)/MAX(1,SUMPRODUCT(('Form Responses 1'!$B$2:$B$500="Mary Wanjiku Pharmacy")*('Form Responses 1'!$E$2:$E$500=A9)*('Form Responses 1'!$F$2:$F$500="Dispensed")*(DATEVALUE(TEXT('Form Responses 1'!$C$2:$C$500,"YYYY-MM-DD"))>=(TODAY()-90)))/7*7)*7,0) | E9: =IFERROR(D9/7,0) | F9: =IFERROR(IF(E9=0,IF(C9>0,999,0),ROUND(C9/E9,0)),0) | G9: 10 | H9: =IF(F9<=0,"STOCKOUT",IF(F9<=7,"CRITICAL",IF(F9<=14,"LOW",IF(F9<=30,"ADEQUATE","GOOD")))) | I9: =IFERROR(TEXT(MINIFS('Batch Register'!$F:$F,'Batch Register'!$A:$A,"Mary Wanjiku Pharmacy",'Batch Register'!$B:$B,A9,'Batch Register'!$G:$G,"Active",'Batch Register'!$F:$F,">"&TODAY()),"YYYY-MM-DD"),"No active batch") | J9: =IF(OR(I9="",I9="No active batch"),"",INT(DATEVALUE(I9)-TODAY())) | K9: =IF(OR(I9="",I9="No active batch"),"OK",IF(J9<=0,"EXPIRED",IF(J9<=30,"EXPIRES SOON",IF(J9<=60,"EXPIRING 60D","OK")))) | L9: =IF(OR(H9="STOCKOUT",H9="CRITICAL",K9="EXPIRED",K9="EXPIRES SOON"),"ACTION NEEDED",IF(OR(H9="LOW",K9="EXPIRING 60D"),"MONITOR","OK")) | M9: 200
A10: Fluconazole 150mg caps | B10: caps | C10: =IFERROR(M10+SUMPRODUCT(('Form Responses 1'!$B$2:$B$500="Mary Wanjiku Pharmacy")*('Form Responses 1'!$E$2:$E$500=A10)*('Form Responses 1'!$F$2:$F$500="Received")*'Form Responses 1'!$G$2:$G$500)-SUMPRODUCT(('Form Responses 1'!$B$2:$B$500="Mary Wanjiku Pharmacy")*('Form Responses 1'!$E$2:$E$500=A10)*('Form Responses 1'!$F$2:$F$500="Dispensed")*'Form Responses 1'!$G$2:$G$500)-SUMPRODUCT(('Form Responses 1'!$B$2:$B$500="Mary Wanjiku Pharmacy")*('Form Responses 1'!$E$2:$E$500=A10)*('Form Responses 1'!$F$2:$F$500="Expired")*'Form Responses 1'!$G$2:$G$500)+SUMPRODUCT(('Form Responses 1'!$B$2:$B$500="Mary Wanjiku Pharmacy")*('Form Responses 1'!$E$2:$E$500=A10)*('Form Responses 1'!$F$2:$F$500="Returned")*'Form Responses 1'!$G$2:$G$500),0) | D10: =IFERROR(SUMPRODUCT(('Form Responses 1'!$B$2:$B$500="Mary Wanjiku Pharmacy")*('Form Responses 1'!$E$2:$E$500=A10)*('Form Responses 1'!$F$2:$F$500="Dispensed")*(DATEVALUE(TEXT('Form Responses 1'!$C$2:$C$500,"YYYY-MM-DD"))>=(TODAY()-90))*'Form Responses 1'!$G$2:$G$500)/MAX(1,SUMPRODUCT(('Form Responses 1'!$B$2:$B$500="Mary Wanjiku Pharmacy")*('Form Responses 1'!$E$2:$E$500=A10)*('Form Responses 1'!$F$2:$F$500="Dispensed")*(DATEVALUE(TEXT('Form Responses 1'!$C$2:$C$500,"YYYY-MM-DD"))>=(TODAY()-90)))/7*7)*7,0) | E10: =IFERROR(D10/7,0) | F10: =IFERROR(IF(E10=0,IF(C10>0,999,0),ROUND(C10/E10,0)),0) | G10: 16 | H10: =IF(F10<=0,"STOCKOUT",IF(F10<=7,"CRITICAL",IF(F10<=14,"LOW",IF(F10<=30,"ADEQUATE","GOOD")))) | I10: =IFERROR(TEXT(MINIFS('Batch Register'!$F:$F,'Batch Register'!$A:$A,"Mary Wanjiku Pharmacy",'Batch Register'!$B:$B,A10,'Batch Register'!$G:$G,"Active",'Batch Register'!$F:$F,">"&TODAY()),"YYYY-MM-DD"),"No active batch") | J10: =IF(OR(I10="",I10="No active batch"),"",INT(DATEVALUE(I10)-TODAY())) | K10: =IF(OR(I10="",I10="No active batch"),"OK",IF(J10<=0,"EXPIRED",IF(J10<=30,"EXPIRES SOON",IF(J10<=60,"EXPIRING 60D","OK")))) | L10: =IF(OR(H10="STOCKOUT",H10="CRITICAL",K10="EXPIRED",K10="EXPIRES SOON"),"ACTION NEEDED",IF(OR(H10="LOW",K10="EXPIRING 60D"),"MONITOR","OK")) | M10: 50
A11: Amoxicillin 500mg caps | B11: caps | C11: =IFERROR(M11+SUMPRODUCT(('Form Responses 1'!$B$2:$B$500="Mary Wanjiku Pharmacy")*('Form Responses 1'!$E$2:$E$500=A11)*('Form Responses 1'!$F$2:$F$500="Received")*'Form Responses 1'!$G$2:$G$500)-SUMPRODUCT(('Form Responses 1'!$B$2:$B$500="Mary Wanjiku Pharmacy")*('Form Responses 1'!$E$2:$E$500=A11)*('Form Responses 1'!$F$2:$F$500="Dispensed")*'Form Responses 1'!$G$2:$G$500)-SUMPRODUCT(('Form Responses 1'!$B$2:$B$500="Mary Wanjiku Pharmacy")*('Form Responses 1'!$E$2:$E$500=A11)*('Form Responses 1'!$F$2:$F$500="Expired")*'Form Responses 1'!$G$2:$G$500)+SUMPRODUCT(('Form Responses 1'!$B$2:$B$500="Mary Wanjiku Pharmacy")*('Form Responses 1'!$E$2:$E$500=A11)*('Form Responses 1'!$F$2:$F$500="Returned")*'Form Responses 1'!$G$2:$G$500),0) | D11: =IFERROR(SUMPRODUCT(('Form Responses 1'!$B$2:$B$500="Mary Wanjiku Pharmacy")*('Form Responses 1'!$E$2:$E$500=A11)*('Form Responses 1'!$F$2:$F$500="Dispensed")*(DATEVALUE(TEXT('Form Responses 1'!$C$2:$C$500,"YYYY-MM-DD"))>=(TODAY()-90))*'Form Responses 1'!$G$2:$G$500)/MAX(1,SUMPRODUCT(('Form Responses 1'!$B$2:$B$500="Mary Wanjiku Pharmacy")*('Form Responses 1'!$E$2:$E$500=A11)*('Form Responses 1'!$F$2:$F$500="Dispensed")*(DATEVALUE(TEXT('Form Responses 1'!$C$2:$C$500,"YYYY-MM-DD"))>=(TODAY()-90)))/7*7)*7,0) | E11: =IFERROR(D11/7,0) | F11: =IFERROR(IF(E11=0,IF(C11>0,999,0),ROUND(C11/E11,0)),0) | G11: 20 | H11: =IF(F11<=0,"STOCKOUT",IF(F11<=7,"CRITICAL",IF(F11<=14,"LOW",IF(F11<=30,"ADEQUATE","GOOD")))) | I11: =IFERROR(TEXT(MINIFS('Batch Register'!$F:$F,'Batch Register'!$A:$A,"Mary Wanjiku Pharmacy",'Batch Register'!$B:$B,A11,'Batch Register'!$G:$G,"Active",'Batch Register'!$F:$F,">"&TODAY()),"YYYY-MM-DD"),"No active batch") | J11: =IF(OR(I11="",I11="No active batch"),"",INT(DATEVALUE(I11)-TODAY())) | K11: =IF(OR(I11="",I11="No active batch"),"OK",IF(J11<=0,"EXPIRED",IF(J11<=30,"EXPIRES SOON",IF(J11<=60,"EXPIRING 60D","OK")))) | L11: =IF(OR(H11="STOCKOUT",H11="CRITICAL",K11="EXPIRED",K11="EXPIRES SOON"),"ACTION NEEDED",IF(OR(H11="LOW",K11="EXPIRING 60D"),"MONITOR","OK")) | M11: 200
A12: Ciprofloxacin 500mg tabs | B12: tabs | C12: =IFERROR(M12+SUMPRODUCT(('Form Responses 1'!$B$2:$B$500="Mary Wanjiku Pharmacy")*('Form Responses 1'!$E$2:$E$500=A12)*('Form Responses 1'!$F$2:$F$500="Received")*'Form Responses 1'!$G$2:$G$500)-SUMPRODUCT(('Form Responses 1'!$B$2:$B$500="Mary Wanjiku Pharmacy")*('Form Responses 1'!$E$2:$E$500=A12)*('Form Responses 1'!$F$2:$F$500="Dispensed")*'Form Responses 1'!$G$2:$G$500)-SUMPRODUCT(('Form Responses 1'!$B$2:$B$500="Mary Wanjiku Pharmacy")*('Form Responses 1'!$E$2:$E$500=A12)*('Form Responses 1'!$F$2:$F$500="Expired")*'Form Responses 1'!$G$2:$G$500)+SUMPRODUCT(('Form Responses 1'!$B$2:$B$500="Mary Wanjiku Pharmacy")*('Form Responses 1'!$E$2:$E$500=A12)*('Form Responses 1'!$F$2:$F$500="Returned")*'Form Responses 1'!$G$2:$G$500),0) | D12: =IFERROR(SUMPRODUCT(('Form Responses 1'!$B$2:$B$500="Mary Wanjiku Pharmacy")*('Form Responses 1'!$E$2:$E$500=A12)*('Form Responses 1'!$F$2:$F$500="Dispensed")*(DATEVALUE(TEXT('Form Responses 1'!$C$2:$C$500,"YYYY-MM-DD"))>=(TODAY()-90))*'Form Responses 1'!$G$2:$G$500)/MAX(1,SUMPRODUCT(('Form Responses 1'!$B$2:$B$500="Mary Wanjiku Pharmacy")*('Form Responses 1'!$E$2:$E$500=A12)*('Form Responses 1'!$F$2:$F$500="Dispensed")*(DATEVALUE(TEXT('Form Responses 1'!$C$2:$C$500,"YYYY-MM-DD"))>=(TODAY()-90)))/7*7)*7,0) | E12: =IFERROR(D12/7,0) | F12: =IFERROR(IF(E12=0,IF(C12>0,999,0),ROUND(C12/E12,0)),0) | G12: 18 | H12: =IF(F12<=0,"STOCKOUT",IF(F12<=7,"CRITICAL",IF(F12<=14,"LOW",IF(F12<=30,"ADEQUATE","GOOD")))) | I12: =IFERROR(TEXT(MINIFS('Batch Register'!$F:$F,'Batch Register'!$A:$A,"Mary Wanjiku Pharmacy",'Batch Register'!$B:$B,A12,'Batch Register'!$G:$G,"Active",'Batch Register'!$F:$F,">"&TODAY()),"YYYY-MM-DD"),"No active batch") | J12: =IF(OR(I12="",I12="No active batch"),"",INT(DATEVALUE(I12)-TODAY())) | K12: =IF(OR(I12="",I12="No active batch"),"OK",IF(J12<=0,"EXPIRED",IF(J12<=30,"EXPIRES SOON",IF(J12<=60,"EXPIRING 60D","OK")))) | L12: =IF(OR(H12="STOCKOUT",H12="CRITICAL",K12="EXPIRED",K12="EXPIRES SOON"),"ACTION NEEDED",IF(OR(H12="LOW",K12="EXPIRING 60D"),"MONITOR","OK")) | M12: 120
A13: Metronidazole 200mg tabs | B13: tabs | C13: =IFERROR(M13+SUMPRODUCT(('Form Responses 1'!$B$2:$B$500="Mary Wanjiku Pharmacy")*('Form Responses 1'!$E$2:$E$500=A13)*('Form Responses 1'!$F$2:$F$500="Received")*'Form Responses 1'!$G$2:$G$500)-SUMPRODUCT(('Form Responses 1'!$B$2:$B$500="Mary Wanjiku Pharmacy")*('Form Responses 1'!$E$2:$E$500=A13)*('Form Responses 1'!$F$2:$F$500="Dispensed")*'Form Responses 1'!$G$2:$G$500)-SUMPRODUCT(('Form Responses 1'!$B$2:$B$500="Mary Wanjiku Pharmacy")*('Form Responses 1'!$E$2:$E$500=A13)*('Form Responses 1'!$F$2:$F$500="Expired")*'Form Responses 1'!$G$2:$G$500)+SUMPRODUCT(('Form Responses 1'!$B$2:$B$500="Mary Wanjiku Pharmacy")*('Form Responses 1'!$E$2:$E$500=A13)*('Form Responses 1'!$F$2:$F$500="Returned")*'Form Responses 1'!$G$2:$G$500),0) | D13: =IFERROR(SUMPRODUCT(('Form Responses 1'!$B$2:$B$500="Mary Wanjiku Pharmacy")*('Form Responses 1'!$E$2:$E$500=A13)*('Form Responses 1'!$F$2:$F$500="Dispensed")*(DATEVALUE(TEXT('Form Responses 1'!$C$2:$C$500,"YYYY-MM-DD"))>=(TODAY()-90))*'Form Responses 1'!$G$2:$G$500)/MAX(1,SUMPRODUCT(('Form Responses 1'!$B$2:$B$500="Mary Wanjiku Pharmacy")*('Form Responses 1'!$E$2:$E$500=A13)*('Form Responses 1'!$F$2:$F$500="Dispensed")*(DATEVALUE(TEXT('Form Responses 1'!$C$2:$C$500,"YYYY-MM-DD"))>=(TODAY()-90)))/7*7)*7,0) | E13: =IFERROR(D13/7,0) | F13: =IFERROR(IF(E13=0,IF(C13>0,999,0),ROUND(C13/E13,0)),0) | G13: 18 | H13: =IF(F13<=0,"STOCKOUT",IF(F13<=7,"CRITICAL",IF(F13<=14,"LOW",IF(F13<=30,"ADEQUATE","GOOD")))) | I13: =IFERROR(TEXT(MINIFS('Batch Register'!$F:$F,'Batch Register'!$A:$A,"Mary Wanjiku Pharmacy",'Batch Register'!$B:$B,A13,'Batch Register'!$G:$G,"Active",'Batch Register'!$F:$F,">"&TODAY()),"YYYY-MM-DD"),"No active batch") | J13: =IF(OR(I13="",I13="No active batch"),"",INT(DATEVALUE(I13)-TODAY())) | K13: =IF(OR(I13="",I13="No active batch"),"OK",IF(J13<=0,"EXPIRED",IF(J13<=30,"EXPIRES SOON",IF(J13<=60,"EXPIRING 60D","OK")))) | L13: =IF(OR(H13="STOCKOUT",H13="CRITICAL",K13="EXPIRED",K13="EXPIRES SOON"),"ACTION NEEDED",IF(OR(H13="LOW",K13="EXPIRING 60D"),"MONITOR","OK")) | M13: 180
A14: Omeprazole 20mg caps | B14: caps | C14: =IFERROR(M14+SUMPRODUCT(('Form Responses 1'!$B$2:$B$500="Mary Wanjiku Pharmacy")*('Form Responses 1'!$E$2:$E$500=A14)*('Form Responses 1'!$F$2:$F$500="Received")*'Form Responses 1'!$G$2:$G$500)-SUMPRODUCT(('Form Responses 1'!$B$2:$B$500="Mary Wanjiku Pharmacy")*('Form Responses 1'!$E$2:$E$500=A14)*('Form Responses 1'!$F$2:$F$500="Dispensed")*'Form Responses 1'!$G$2:$G$500)-SUMPRODUCT(('Form Responses 1'!$B$2:$B$500="Mary Wanjiku Pharmacy")*('Form Responses 1'!$E$2:$E$500=A14)*('Form Responses 1'!$F$2:$F$500="Expired")*'Form Responses 1'!$G$2:$G$500)+SUMPRODUCT(('Form Responses 1'!$B$2:$B$500="Mary Wanjiku Pharmacy")*('Form Responses 1'!$E$2:$E$500=A14)*('Form Responses 1'!$F$2:$F$500="Returned")*'Form Responses 1'!$G$2:$G$500),0) | D14: =IFERROR(SUMPRODUCT(('Form Responses 1'!$B$2:$B$500="Mary Wanjiku Pharmacy")*('Form Responses 1'!$E$2:$E$500=A14)*('Form Responses 1'!$F$2:$F$500="Dispensed")*(DATEVALUE(TEXT('Form Responses 1'!$C$2:$C$500,"YYYY-MM-DD"))>=(TODAY()-90))*'Form Responses 1'!$G$2:$G$500)/MAX(1,SUMPRODUCT(('Form Responses 1'!$B$2:$B$500="Mary Wanjiku Pharmacy")*('Form Responses 1'!$E$2:$E$500=A14)*('Form Responses 1'!$F$2:$F$500="Dispensed")*(DATEVALUE(TEXT('Form Responses 1'!$C$2:$C$500,"YYYY-MM-DD"))>=(TODAY()-90)))/7*7)*7,0) | E14: =IFERROR(D14/7,0) | F14: =IFERROR(IF(E14=0,IF(C14>0,999,0),ROUND(C14/E14,0)),0) | G14: 18 | H14: =IF(F14<=0,"STOCKOUT",IF(F14<=7,"CRITICAL",IF(F14<=14,"LOW",IF(F14<=30,"ADEQUATE","GOOD")))) | I14: =IFERROR(TEXT(MINIFS('Batch Register'!$F:$F,'Batch Register'!$A:$A,"Mary Wanjiku Pharmacy",'Batch Register'!$B:$B,A14,'Batch Register'!$G:$G,"Active",'Batch Register'!$F:$F,">"&TODAY()),"YYYY-MM-DD"),"No active batch") | J14: =IF(OR(I14="",I14="No active batch"),"",INT(DATEVALUE(I14)-TODAY())) | K14: =IF(OR(I14="",I14="No active batch"),"OK",IF(J14<=0,"EXPIRED",IF(J14<=30,"EXPIRES SOON",IF(J14<=60,"EXPIRING 60D","OK")))) | L14: =IF(OR(H14="STOCKOUT",H14="CRITICAL",K14="EXPIRED",K14="EXPIRES SOON"),"ACTION NEEDED",IF(OR(H14="LOW",K14="EXPIRING 60D"),"MONITOR","OK")) | M14: 200
A15: Atenolol 50mg tabs | B15: tabs | C15: =IFERROR(M15+SUMPRODUCT(('Form Responses 1'!$B$2:$B$500="Mary Wanjiku Pharmacy")*('Form Responses 1'!$E$2:$E$500=A15)*('Form Responses 1'!$F$2:$F$500="Received")*'Form Responses 1'!$G$2:$G$500)-SUMPRODUCT(('Form Responses 1'!$B$2:$B$500="Mary Wanjiku Pharmacy")*('Form Responses 1'!$E$2:$E$500=A15)*('Form Responses 1'!$F$2:$F$500="Dispensed")*'Form Responses 1'!$G$2:$G$500)-SUMPRODUCT(('Form Responses 1'!$B$2:$B$500="Mary Wanjiku Pharmacy")*('Form Responses 1'!$E$2:$E$500=A15)*('Form Responses 1'!$F$2:$F$500="Expired")*'Form Responses 1'!$G$2:$G$500)+SUMPRODUCT(('Form Responses 1'!$B$2:$B$500="Mary Wanjiku Pharmacy")*('Form Responses 1'!$E$2:$E$500=A15)*('Form Responses 1'!$F$2:$F$500="Returned")*'Form Responses 1'!$G$2:$G$500),0) | D15: =IFERROR(SUMPRODUCT(('Form Responses 1'!$B$2:$B$500="Mary Wanjiku Pharmacy")*('Form Responses 1'!$E$2:$E$500=A15)*('Form Responses 1'!$F$2:$F$500="Dispensed")*(DATEVALUE(TEXT('Form Responses 1'!$C$2:$C$500,"YYYY-MM-DD"))>=(TODAY()-90))*'Form Responses 1'!$G$2:$G$500)/MAX(1,SUMPRODUCT(('Form Responses 1'!$B$2:$B$500="Mary Wanjiku Pharmacy")*('Form Responses 1'!$E$2:$E$500=A15)*('Form Responses 1'!$F$2:$F$500="Dispensed")*(DATEVALUE(TEXT('Form Responses 1'!$C$2:$C$500,"YYYY-MM-DD"))>=(TODAY()-90)))/7*7)*7,0) | E15: =IFERROR(D15/7,0) | F15: =IFERROR(IF(E15=0,IF(C15>0,999,0),ROUND(C15/E15,0)),0) | G15: 24 | H15: =IF(F15<=0,"STOCKOUT",IF(F15<=7,"CRITICAL",IF(F15<=14,"LOW",IF(F15<=30,"ADEQUATE","GOOD")))) | I15: =IFERROR(TEXT(MINIFS('Batch Register'!$F:$F,'Batch Register'!$A:$A,"Mary Wanjiku Pharmacy",'Batch Register'!$B:$B,A15,'Batch Register'!$G:$G,"Active",'Batch Register'!$F:$F,">"&TODAY()),"YYYY-MM-DD"),"No active batch") | J15: =IF(OR(I15="",I15="No active batch"),"",INT(DATEVALUE(I15)-TODAY())) | K15: =IF(OR(I15="",I15="No active batch"),"OK",IF(J15<=0,"EXPIRED",IF(J15<=30,"EXPIRES SOON",IF(J15<=60,"EXPIRING 60D","OK")))) | L15: =IF(OR(H15="STOCKOUT",H15="CRITICAL",K15="EXPIRED",K15="EXPIRES SOON"),"ACTION NEEDED",IF(OR(H15="LOW",K15="EXPIRING 60D"),"MONITOR","OK")) | M15: 300
... A23: Doxycycline 100mg caps | B23: caps | C23: =IFERROR(M23+SUMPRODUCT(('Form Responses 1'!$B$2:$B$500="Mary Wanjiku Pharmacy")*('Form Responses 1'!$E$2:$E$500=A23)*('Form Responses 1'!$F$2:$F$500="Received")*'Form Responses 1'!$G$2:$G$500)-SUMPRODUCT(('Form Responses 1'!$B$2:$B$500="Mary Wanjiku Pharmacy")*('Form Responses 1'!$E$2:$E$500=A23)*('Form Responses 1'!$F$2:$F$500="Dispensed")*'Form Responses 1'!$G$2:$G$500)-SUMPRODUCT(('Form Responses 1'!$B$2:$B$500="Mary Wanjiku Pharmacy")*('Form Responses 1'!$E$2:$E$500=A23)*('Form Responses 1'!$F$2:$F$500="Expired")*'Form Responses 1'!$G$2:$G$500)+SUMPRODUCT(('Form Responses 1'!$B$2:$B$500="Mary Wanjiku Pharmacy")*('Form Responses 1'!$E$2:$E$500=A23)*('Form Responses 1'!$F$2:$F$500="Returned")*'Form Responses 1'!$G$2:$G$500),0) | D23: =IFERROR(SUMPRODUCT(('Form Responses 1'!$B$2:$B$500="Mary Wanjiku Pharmacy")*('Form Responses 1'!$E$2:$E$500=A23)*('Form Responses 1'!$F$2:$F$500="Dispensed")*(DATEVALUE(TEXT('Form Responses 1'!$C$2:$C$500,"YYYY-MM-DD"))>=(TODAY()-90))*'Form Responses 1'!$G$2:$G$500)/MAX(1,SUMPRODUCT(('Form Responses 1'!$B$2:$B$500="Mary Wanjiku Pharmacy")*('Form Responses 1'!$E$2:$E$500=A23)*('Form Responses 1'!$F$2:$F$500="Dispensed")*(DATEVALUE(TEXT('Form Responses 1'!$C$2:$C$500,"YYYY-MM-DD"))>=(TODAY()-90)))/7*7)*7,0) | E23: =IFERROR(D23/7,0) | F23: =IFERROR(IF(E23=0,IF(C23>0,999,0),ROUND(C23/E23,0)),0) | G23: 16 | H23: =IF(F23<=0,"STOCKOUT",IF(F23<=7,"CRITICAL",IF(F23<=14,"LOW",IF(F23<=30,"ADEQUATE","GOOD")))) | I23: =IFERROR(TEXT(MINIFS('Batch Register'!$F:$F,'Batch Register'!$A:$A,"Mary Wanjiku Pharmacy",'Batch Register'!$B:$B,A23,'Batch Register'!$G:$G,"Active",'Batch Register'!$F:$F,">"&TODAY()),"YYYY-MM-DD"),"No active batch") | J23: =IF(OR(I23="",I23="No active batch"),"",INT(DATEVALUE(I23)-TODAY())) | K23: =IF(OR(I23="",I23="No active batch"),"OK",IF(J23<=0,"EXPIRED",IF(J23<=30,"EXPIRES SOON",IF(J23<=60,"EXPIRING 60D","OK")))) | L23: =IF(OR(H23="STOCKOUT",H23="CRITICAL",K23="EXPIRED",K23="EXPIRES SOON"),"ACTION NEEDED",IF(OR(H23="LOW",K23="EXPIRING 60D"),"MONITOR","OK")) | M23: 100

Sheet Batch Register
A1: ⬡ DAWA INTEL — BATCH REGISTER | Add one row per received batch, any pharmacy
A2: Status options: Active (in stock) · Depleted (fully dispensed) · Expired (past date, not dispensed) | Column H auto-calculates days to expiry. Negative = already expired.
A3: Pharmacy Name | B3: Drug Name | C3: Batch Ref | D3: Qty Received | E3: Date Received | F3: Expiry Date ★ | G3: Status | H3: Days to Expiry
A4: Mary Wanjiku Pharmacy | B4: Metformin 500mg tabs | C4: BN2501-MF | D4: 500 | E4: 2026-05-28 | F4: 2027-08-27 | G4: Active | H4: =IF(OR(G4="Depleted",F4=""),"—",INT(F4-TODAY()))
A5: Mary Wanjiku Pharmacy | B5: Paracetamol 500mg tabs | C5: BN2501-PC | D5: 800 | E5: 2026-05-28 | F5: 2027-12-05 | G5: Active | H5: =IF(OR(G5="Depleted",F5=""),"—",INT(F5-TODAY()))
A6: Mary Wanjiku Pharmacy | B6: Amoxicillin 250mg caps | C6: BN2502-AM2 | D6: 400 | E6: 2026-06-11 | F6: 2027-05-19 | G6: Active | H6: =IF(OR(G6="Depleted",F6=""),"—",INT(F6-TODAY()))
A7: Mary Wanjiku Pharmacy | B7: Amlodipine 5mg tabs | C7: AM240901 | D7: 300 | E7: 2026-05-24 | F7: 2026-09-06 | G7: Active | H7: =IF(OR(G7="Depleted",F7=""),"—",INT(F7-TODAY()))
A8: Mary Wanjiku Pharmacy | B8: Ibuprofen 400mg tabs | C8: BN2501-IB | D8: 150 | E8: 2026-06-08 | F8: 2028-03-14 | G8: Active | H8: =IF(OR(G8="Depleted",F8=""),"—",INT(F8-TODAY()))
A9: Mary Wanjiku Pharmacy | B9: ORS Sachet | C9: BN2503-ORS | D9: 200 | E9: 2026-06-23 | F9: 2028-06-22 | G9: Active | H9: =IF(OR(G9="Depleted",F9=""),"—",INT(F9-TODAY()))
A10: Mary Wanjiku Pharmacy | B10: Fluconazole 150mg caps | C10: FL2401-OLD | D10: 50 | E10: 2026-05-14 | F10: 2026-07-18 | G10: Depleted | H10: =IF(OR(G10="Depleted",F10=""),"—",INT(F10-TODAY()))
A11: Mary Wanjiku Pharmacy | B11: Amoxicillin 500mg caps | C11: BN2502-AM5 | D11: 200 | E11: 2026-06-13 | F11: 2027-08-27 | G11: Active | H11: =IF(OR(G11="Depleted",F11=""),"—",INT(F11-TODAY()))
A12: Mary Wanjiku Pharmacy | B12: Ciprofloxacin 500mg tabs | C12: BN2502-CP | D12: 120 | E12: 2026-06-18 | F12: 2027-12-05 | G12: Active | H12: =IF(OR(G12="Depleted",F12=""),"—",INT(F12-TODAY()))
A13: Mary Wanjiku Pharmacy | B13: Omeprazole 20mg caps | C13: BN2503-OM | D13: 200 | E13: 2026-06-25 | F13: 2027-10-16 | G13: Active | H13: =IF(OR(G13="Depleted",F13=""),"—",INT(F13-TODAY()))
A14: Mary Wanjiku Pharmacy | B14: Salbutamol 100mcg inhaler | C14: BN2501-SB | D14: 20 | E14: 2026-06-08 | F14: 2028-06-22 | G14: Active | H14: =IF(OR(G14="Depleted",F14=""),"—",INT(F14-TODAY()))
A15: Mary Wanjiku Pharmacy | B15: Losartan 50mg tabs | C15: BN2502-LO | D15: 240 | E15: 2026-06-13 | F15: 2027-12-05 | G15: Active | H15: =IF(OR(G15="Depleted",F15=""),"—",INT(F15-TODAY()))
... A17: Mary Wanjiku Pharmacy | B17: Metronidazole 200mg tabs | C17: BN2503-MT | D17: 180 | E17: 2026-07-15 | F17: 2027-12-05 | G17: Active | H17: =IF(OR(G17="Depleted",F17=""),"—",INT(F17-TODAY()))

Sheet Overview Dashboard
A1: ⬡ DAWA INTEL — OVERVIEW DASHBOARD | Check every Sunday evening
A2: Auto-updates as Form Responses arrive | Last rebuilt: 23 Jul 2026 | Add more pharmacies below as you onboard them
B4: Stockouts | C4: Critical | D4: Low Stock | E4: Expiry Warnings | F4: Expired Batches | G4: Action Needed ★
B5: =COUNTIF('Mary Wanjiku Pharmacy'!H4:H23,"STOCKOUT") | C5: =COUNTIF('Mary Wanjiku Pharmacy'!H4:H23,"CRITICAL") | D5: =COUNTIF('Mary Wanjiku Pharmacy'!H4:H23,"LOW") | E5: =COUNTIF('Mary Wanjiku Pharmacy'!K4:K23,"EXPIRES SOON")+COUNTIF('Mary Wanjiku Pharmacy'!K4:K23,"EXPIRING 60D") | F5: =COUNTIF('Mary Wanjiku Pharmacy'!K4:K23,"EXPIRED") | G5: =COUNTIF('Mary Wanjiku Pharmacy'!L4:L23,"ACTION NEEDED")
A8: PHARMACY SUMMARY — Add one row per enrolled pharmacy
A9: Pharmacy | B9: Drugs Tracked | C9: Stockouts | D9: Critical | E9: Low Stock | F9: Expiry Flags | G9: Action Items | H9: Avg Days Stock
A10: Mary Wanjiku Pharmacy | B10: =COUNTA('Mary Wanjiku Pharmacy'!A4:A23) | C10: =COUNTIF('Mary Wanjiku Pharmacy'!H4:H23,"STOCKOUT") | D10: =COUNTIF('Mary Wanjiku Pharmacy'!H4:H23,"CRITICAL") | E10: =COUNTIF('Mary Wanjiku Pharmacy'!H4:H23,"LOW") | F10: =COUNTIF('Mary Wanjiku Pharmacy'!K4:K23,"EXPIRES SOON")+COUNTIF('Mary Wanjiku Pharmacy'!K4:K23,"EXPIRING 60D") | G10: =COUNTIF('Mary Wanjiku Pharmacy'!L4:L23,"ACTION NEEDED") | H10: =IFERROR(AVERAGEIF('Mary Wanjiku Pharmacy'!F4:F23,"<999"),"No data")
A11: [Duplicate Mary Wanjiku tab → rename → add here]
A12: [Duplicate Mary Wanjiku tab → rename → add here]
A13: [Duplicate Mary Wanjiku tab → rename → add here]
A16: HOW TO ADD A PHARMACY: Duplicate 'Mary Wanjiku Pharmacy' tab → Rename it exactly → Update col A (drug names) → Enter opening stocks in col M → Add to Form dropdown → Add a summary row above (rows 11–13) with COUNTIF formulas pointing to the new tab name.

Sheet Form Responses 1
A1: Timestamp | B1: Pharmacy Name | C1: Date | D1: Staff Name | E1: Drug Name | F1: Movement Type | G1: Quantity | H1: Expiry Date (if Received) | I1: Notes
A2: 2026-05-28 08:06:00 | B2: Mary Wanjiku Pharmacy | C2: 2026-05-28 | D2: Jane Muthoni | E2: Metformin 500mg tabs | F2: Received | G2: 500 | H2: 2027-08-27 | I2: Supplier: Surgipharm BN2501
A3: 2026-05-30 08:09:00 | B3: Mary Wanjiku Pharmacy | C3: 2026-05-30 | D3: Jane Muthoni | E3: Metformin 500mg tabs | F3: Dispensed | G3: 78
A4: 2026-06-06 08:12:00 | B4: Mary Wanjiku Pharmacy | C4: 2026-06-06 | D4: Jane Muthoni | E4: Metformin 500mg tabs | F4: Dispensed | G4: 82
A5: 2026-06-13 08:15:00 | B5: Mary Wanjiku Pharmacy | C5: 2026-06-13 | D5: Jane Muthoni | E5: Metformin 500mg tabs | F5: Dispensed | G5: 79
A6: 2026-06-20 08:18:00 | B6: Mary Wanjiku Pharmacy | C6: 2026-06-20 | D6: Jane Muthoni | E6: Metformin 500mg tabs | F6: Dispensed | G6: 83
A7: 2026-06-27 08:21:00 | B7: Mary Wanjiku Pharmacy | C7: 2026-06-27 | D7: Jane Muthoni | E7: Metformin 500mg tabs | F7: Dispensed | G7: 77
A8: 2026-07-04 08:24:00 | B8: Mary Wanjiku Pharmacy | C8: 2026-07-04 | D8: Jane Muthoni | E8: Metformin 500mg tabs | F8: Dispensed | G8: 81
A9: 2026-07-11 08:27:00 | B9: Mary Wanjiku Pharmacy | C9: 2026-07-11 | D9: Jane Muthoni | E9: Metformin 500mg tabs | F9: Dispensed | G9: 80
A10: 2026-07-18 08:30:00 | B10: Mary Wanjiku Pharmacy | C10: 2026-07-18 | D10: Jane Muthoni | E10: Metformin 500mg tabs | F10: Dispensed | G10: 84
A11: 2026-05-28 08:33:00 | B11: Mary Wanjiku Pharmacy | C11: 2026-05-28 | D11: Jane Muthoni | E11: Paracetamol 500mg tabs | F11: Received | G11: 800 | H11: 2027-12-05 | I11: Bulk order
A12: 2026-05-30 08:36:00 | B12: Mary Wanjiku Pharmacy | C12: 2026-05-30 | D12: Jane Muthoni | E12: Paracetamol 500mg tabs | F12: Dispensed | G12: 195
A13: 2026-06-06 08:39:00 | B13: Mary Wanjiku Pharmacy | C13: 2026-06-06 | D13: Jane Muthoni | E13: Paracetamol 500mg tabs | F13: Dispensed | G13: 210
A14: 2026-06-13 08:42:00 | B14: Mary Wanjiku Pharmacy | C14: 2026-06-13 | D14: Jane Muthoni | E14: Paracetamol 500mg tabs | F14: Dispensed | G14: 198
A15: 2026-06-20 08:45:00 | B15: Mary Wanjiku Pharmacy | C15: 2026-06-20 | D15: Jane Muthoni | E15: Paracetamol 500mg tabs | F15: Dispensed | G15: 205
A16: 2026-06-27 08:48:00 | B16: Mary Wanjiku Pharmacy | C16: 2026-06-27 | D16: Jane Muthoni | E16: Paracetamol 500mg tabs | F16: Dispensed | G16: 202
A17: 2026-07-04 08:51:00 | B17: Mary Wanjiku Pharmacy | C17: 2026-07-04 | D17: Jane Muthoni | E17: Paracetamol 500mg tabs | F17: Dispensed | G17: 208
A18: 2026-07-11 08:54:00 | B18: Mary Wanjiku Pharmacy | C18: 2026-07-11 | D18: Jane Muthoni | E18: Paracetamol 500mg tabs | F18: Dispensed | G18: 196
A19: 2026-07-18 08:57:00 | B19: Mary Wanjiku Pharmacy | C19: 2026-07-18 | D19: Jane Muthoni | E19: Paracetamol 500mg tabs | F19: Dispensed | G19: 203
A20: 2026-06-11 08:02:00 | B20: Mary Wanjiku Pharmacy | C20: 2026-06-11 | D20: Peter Kamau | E20: Amoxicillin 250mg caps | F20: Received | G20: 400 | H20: 2027-05-19
A21: 2026-06-13 08:05:00 | B21: Mary Wanjiku Pharmacy | C21: 2026-06-13 | D21: Peter Kamau | E21: Amoxicillin 250mg caps | F21: Dispensed | G21: 115 | I21: School season
A22: 2026-06-20 08:08:00 | B22: Mary Wanjiku Pharmacy | C22: 2026-06-20 | D22: Peter Kamau | E22: Amoxicillin 250mg caps | F22: Dispensed | G22: 120
A23: 2026-06-27 08:11:00 | B23: Mary Wanjiku Pharmacy | C23: 2026-06-27 | D23: Peter Kamau | E23: Amoxicillin 250mg caps | F23: Dispensed | G23: 118
A24: 2026-07-04 08:14:00 | B24: Mary Wanjiku Pharmacy | C24: 2026-07-04 | D24: Peter Kamau | E24: Amoxicillin 250mg caps | F24: Dispensed | G24: 122
A25: 2026-07-11 08:17:00 | B25: Mary Wanjiku Pharmacy | C25: 2026-07-11 | D25: Peter Kamau | E25: Amoxicillin 250mg caps | F25: Dispensed | G25: 116
A26: 2026-07-18 08:20:00 | B26: Mary Wanjiku Pharmacy | C26: 2026-07-18 | D26: Peter Kamau | E26: Amoxicillin 250mg caps | F26: Dispensed | G26: 119
A27: 2026-05-24 08:23:00 | B27: Mary Wanjiku Pharmacy | C27: 2026-05-24 | D27: Jane Muthoni | E27: Amlodipine 5mg tabs | F27: Received | G27: 300 | H27: 2026-09-06 | I27: Batch AM240901 — note expiry
A28: 2026-05-27 08:26:00 | B28: Mary Wanjiku Pharmacy | C28: 2026-05-27 | D28: Jane Muthoni | E28: Amlodipine 5mg tabs | F28: Dispensed | G28: 65
A29: 2026-06-03 08:29:00 | B29: Mary Wanjiku Pharmacy | C29: 2026-06-03 | D29: Jane Muthoni | E29: Amlodipine 5mg tabs | F29: Dispensed | G29: 68
A30: 2026-06-10 08:32:00 | B30: Mary Wanjiku Pharmacy | C30: 2026-06-10 | D30: Jane Muthoni | E30: Amlodipine 5mg tabs | F30: Dispensed | G30: 64
A31: 2026-06-17 08:35:00 | B31: Mary Wanjiku Pharmacy | C31: 2026-06-17 | D31: Jane Muthoni | E31: Amlodipine 5mg tabs | F31: Dispensed | G31: 70
A32: 2026-06-24 08:38:00 | B32: Mary Wanjiku Pharmacy | C32: 2026-06-24 | D32: Jane Muthoni | E32: Amlodipine 5mg tabs | F32: Dispensed | G32: 67
A33: 2026-07-01 08:41:00 | B33: Mary Wanjiku Pharmacy | C33: 2026-07-01 | D33: Jane Muthoni | E33: Amlodipine 5mg tabs | F33: Dispensed | G33: 69
A34: 2026-07-08 08:44:00 | B34: Mary Wanjiku Pharmacy | C34: 2026-07-08 | D34: Jane Muthoni | E34: Amlodipine 5mg tabs | F34: Dispensed | G34: 63
A35: 2026-07-15 08:47:00 | B35: Mary Wanjiku Pharmacy | C35: 2026-07-15 | D35: Jane Muthoni | E35: Amlodipine 5mg tabs | F35: Dispensed | G35: 71
A36: 2026-06-08 08:50:00 | B36: Mary Wanjiku Pharmacy | C36: 2026-06-08 | D36: Peter Kamau | E36: Ibuprofen 400mg tabs | F36: Received | G36: 150 | H36: 2028-03-14
A37: 2026-06-10 08:53:00 | B37: Mary Wanjiku Pharmacy | C37: 2026-06-10 | D37: Peter Kamau | E37: Ibuprofen 400mg tabs | F37: Dispensed | G37: 88
A38: 2026-06-17 08:56:00 | B38: Mary Wanjiku Pharmacy | C38: 2026-06-17 | D38: Peter Kamau | E38: Ibuprofen 400mg tabs | F38: Dispensed | G38: 95
A39: 2026-06-24 08:01:00 | B39: Mary Wanjiku Pharmacy | C39: 2026-06-24 | D39: Peter Kamau | E39: Ibuprofen 400mg tabs | F39: Dispensed | G39: 90
A40: 2026-07-01 08:04:00 | B40: Mary Wanjiku Pharmacy | C40: 2026-07-01 | D40: Peter Kamau | E40: Ibuprofen 400mg tabs | F40: Dispensed | G40: 92
...
