Workbook

Sheet Dashboard
B2: PRINTING MEDIA CO. — FINANCE MANAGEMENT DASHBOARD
B3: Live overview of branch income, expenses and net position — updates automatically from Daily Transactions
B5: Report Month (0 = All months): | E5: 0 | F5: <- Enter 1-12 to filter dashboard to a single month, or 0 for all months to date
B6: Report Year (0 = All years): | E6: 0
B9: TOTAL INCOME | E9: TOTAL EXPENSES | H9: NET POSITION | K9: SUPPLIER CLAIMS (PENDING)
B10: =SUMPRODUCT(('Daily Transactions'!$C$6:$C$500="Income")*(($E$5=0)+(MONTH('Daily Transactions'!$A$6:$A$500)=$E$5))*(($E$6=0)+(YEAR('Daily Transactions'!$A$6:$A$500)=$E$6))*'Daily Transactions'!$F$6:$F$500) -> 0 | E10: =SUMPRODUCT(('Daily Transactions'!$C$6:$C$500="Expense")*(($E$5=0)+(MONTH('Daily Transactions'!$A$6:$A$500)=$E$5))*(($E$6=0)+(YEAR('Daily Transactions'!$A$6:$A$500)=$E$6))*'Daily Transactions'!$F$6:$F$500) -> 0 | H10: =B10-E10 -> 0 | K10: =SUMIFS('Supplier Claims'!$F:$F,'Supplier Claims'!$G:$G,"Pending") -> 0
B14: BRANCH PERFORMANCE (filtered by month/year above)
B15: Branch | C15: Location | D15: Income | E15: Salaries | F15: KPLC | G15: Wifi | H15: Rent | I15: Supplier Claims | J15: Other Exp. | K15: Net
B16: China Ndogo | C16: Nairobi | D16: =SUMPRODUCT(('Daily Transactions'!$B$6:$B$500=$B16)*('Daily Transactions'!$C$6:$C$500="Income")*(($E$5=0)+(MONTH('Daily Transactions'!$A$6:$A$500)=$E$5))*(($E$6=0)+(YEAR('Daily Transactions'!$A$6:$A$500)=$E$6))*'Daily Transactions'!$F$6:$F$500) -> 0 | E16: =SUMPRODUCT(('Daily Transactions'!$B$6:$B$500=$B16)*('Daily Transactions'!$D$6:$D$500="Employee Salaries")*(($E$5=0)+(MONTH('Daily Transactions'!$A$6:$A$500)=$E$5))*(($E$6=0)+(YEAR('Daily Transactions'!$A$6:$A$500)=$E$6))*'Daily Transactions'!$F$6:$F$500) -> 0 | F16: =SUMPRODUCT(('Daily Transactions'!$B$6:$B$500=$B16)*('Daily Transactions'!$D$6:$D$500="KPLC")*(($E$5=0)+(MONTH('Daily Transactions'!$A$6:$A$500)=$E$5))*(($E$6=0)+(YEAR('Daily Transactions'!$A$6:$A$500)=$E$6))*'Daily Transactions'!$F$6:$F$500) -> 0 | G16: =SUMPRODUCT(('Daily Transactions'!$B$6:$B$500=$B16)*('Daily Transactions'!$D$6:$D$500="Wifi")*(($E$5=0)+(MONTH('Daily Transactions'!$A$6:$A$500)=$E$5))*(($E$6=0)+(YEAR('Daily Transactions'!$A$6:$A$500)=$E$6))*'Daily Transactions'!$F$6:$F$500) -> 0 | H16: =SUMPRODUCT(('Daily Transactions'!$B$6:$B$500=$B16)*('Daily Transactions'!$D$6:$D$500="Rent")*(($E$5=0)+(MONTH('Daily Transactions'!$A$6:$A$500)=$E$5))*(($E$6=0)+(YEAR('Daily Transactions'!$A$6:$A$500)=$E$6))*'Daily Transactions'!$F$6:$F$500) -> 0 | I16: =SUMPRODUCT(('Daily Transactions'!$B$6:$B$500=$B16)*('Daily Transactions'!$D$6:$D$500="Supplier Claims")*(($E$5=0)+(MONTH('Daily Transactions'!$A$6:$A$500)=$E$5))*(($E$6=0)+(YEAR('Daily Transactions'!$A$6:$A$500)=$E$6))*'Daily Transactions'!$F$6:$F$500) -> 0 | J16: =SUMPRODUCT(('Daily Transactions'!$B$6:$B$500=$B16)*('Daily Transactions'!$D$6:$D$500="Other Expense")*(($E$5=0)+(MONTH('Daily Transactions'!$A$6:$A$500)=$E$5))*(($E$6=0)+(YEAR('Daily Transactions'!$A$6:$A$500)=$E$6))*'Daily Transactions'!$F$6:$F$500) -> 0 | K16: =D16-SUM(E16:J16) -> 0
B17: Yhe Cut | C17: Nakuru | D17: =SUMPRODUCT(('Daily Transactions'!$B$6:$B$500=$B17)*('Daily Transactions'!$C$6:$C$500="Income")*(($E$5=0)+(MONTH('Daily Transactions'!$A$6:$A$500)=$E$5))*(($E$6=0)+(YEAR('Daily Transactions'!$A$6:$A$500)=$E$6))*'Daily Transactions'!$F$6:$F$500) -> 0 | E17: =SUMPRODUCT(('Daily Transactions'!$B$6:$B$500=$B17)*('Daily Transactions'!$D$6:$D$500="Employee Salaries")*(($E$5=0)+(MONTH('Daily Transactions'!$A$6:$A$500)=$E$5))*(($E$6=0)+(YEAR('Daily Transactions'!$A$6:$A$500)=$E$6))*'Daily Transactions'!$F$6:$F$500) -> 0 | F17: =SUMPRODUCT(('Daily Transactions'!$B$6:$B$500=$B17)*('Daily Transactions'!$D$6:$D$500="KPLC")*(($E$5=0)+(MONTH('Daily Transactions'!$A$6:$A$500)=$E$5))*(($E$6=0)+(YEAR('Daily Transactions'!$A$6:$A$500)=$E$6))*'Daily Transactions'!$F$6:$F$500) -> 0 | G17: =SUMPRODUCT(('Daily Transactions'!$B$6:$B$500=$B17)*('Daily Transactions'!$D$6:$D$500="Wifi")*(($E$5=0)+(MONTH('Daily Transactions'!$A$6:$A$500)=$E$5))*(($E$6=0)+(YEAR('Daily Transactions'!$A$6:$A$500)=$E$6))*'Daily Transactions'!$F$6:$F$500) -> 0 | H17: =SUMPRODUCT(('Daily Transactions'!$B$6:$B$500=$B17)*('Daily Transactions'!$D$6:$D$500="Rent")*(($E$5=0)+(MONTH('Daily Transactions'!$A$6:$A$500)=$E$5))*(($E$6=0)+(YEAR('Daily Transactions'!$A$6:$A$500)=$E$6))*'Daily Transactions'!$F$6:$F$500) -> 0 | I17: =SUMPRODUCT(('Daily Transactions'!$B$6:$B$500=$B17)*('Daily Transactions'!$D$6:$D$500="Supplier Claims")*(($E$5=0)+(MONTH('Daily Transactions'!$A$6:$A$500)=$E$5))*(($E$6=0)+(YEAR('Daily Transactions'!$A$6:$A$500)=$E$6))*'Daily Transactions'!$F$6:$F$500) -> 0 | J17: =SUMPRODUCT(('Daily Transactions'!$B$6:$B$500=$B17)*('Daily Transactions'!$D$6:$D$500="Other Expense")*(($E$5=0)+(MONTH('Daily Transactions'!$A$6:$A$500)=$E$5))*(($E$6=0)+(YEAR('Daily Transactions'!$A$6:$A$500)=$E$6))*'Daily Transactions'!$F$6:$F$500) -> 0 | K17: =D17-SUM(E17:J17) -> 0
B18: Heri Ads | C18: Eldoret | D18: =SUMPRODUCT(('Daily Transactions'!$B$6:$B$500=$B18)*('Daily Transactions'!$C$6:$C$500="Income")*(($E$5=0)+(MONTH('Daily Transactions'!$A$6:$A$500)=$E$5))*(($E$6=0)+(YEAR('Daily Transactions'!$A$6:$A$500)=$E$6))*'Daily Transactions'!$F$6:$F$500) -> 0 | E18: =SUMPRODUCT(('Daily Transactions'!$B$6:$B$500=$B18)*('Daily Transactions'!$D$6:$D$500="Employee Salaries")*(($E$5=0)+(MONTH('Daily Transactions'!$A$6:$A$500)=$E$5))*(($E$6=0)+(YEAR('Daily Transactions'!$A$6:$A$500)=$E$6))*'Daily Transactions'!$F$6:$F$500) -> 0 | F18: =SUMPRODUCT(('Daily Transactions'!$B$6:$B$500=$B18)*('Daily Transactions'!$D$6:$D$500="KPLC")*(($E$5=0)+(MONTH('Daily Transactions'!$A$6:$A$500)=$E$5))*(($E$6=0)+(YEAR('Daily Transactions'!$A$6:$A$500)=$E$6))*'Daily Transactions'!$F$6:$F$500) -> 0 | G18: =SUMPRODUCT(('Daily Transactions'!$B$6:$B$500=$B18)*('Daily Transactions'!$D$6:$D$500="Wifi")*(($E$5=0)+(MONTH('Daily Transactions'!$A$6:$A$500)=$E$5))*(($E$6=0)+(YEAR('Daily Transactions'!$A$6:$A$500)=$E$6))*'Daily Transactions'!$F$6:$F$500) -> 0 | H18: =SUMPRODUCT(('Daily Transactions'!$B$6:$B$500=$B18)*('Daily Transactions'!$D$6:$D$500="Rent")*(($E$5=0)+(MONTH('Daily Transactions'!$A$6:$A$500)=$E$5))*(($E$6=0)+(YEAR('Daily Transactions'!$A$6:$A$500)=$E$6))*'Daily Transactions'!$F$6:$F$500) -> 0 | I18: =SUMPRODUCT(('Daily Transactions'!$B$6:$B$500=$B18)*('Daily Transactions'!$D$6:$D$500="Supplier Claims")*(($E$5=0)+(MONTH('Daily Transactions'!$A$6:$A$500)=$E$5))*(($E$6=0)+(YEAR('Daily Transactions'!$A$6:$A$500)=$E$6))*'Daily Transactions'!$F$6:$F$500) -> 0 | J18: =SUMPRODUCT(('Daily Transactions'!$B$6:$B$500=$B18)*('Daily Transactions'!$D$6:$D$500="Other Expense")*(($E$5=0)+(MONTH('Daily Transactions'!$A$6:$A$500)=$E$5))*(($E$6=0)+(YEAR('Daily Transactions'!$A$6:$A$500)=$E$6))*'Daily Transactions'!$F$6:$F$500) -> 0 | K18: =D18-SUM(E18:J18) -> 0
B19: Brands Point | C19: Ravine | D19: =SUMPRODUCT(('Daily Transactions'!$B$6:$B$500=$B19)*('Daily Transactions'!$C$6:$C$500="Income")*(($E$5=0)+(MONTH('Daily Transactions'!$A$6:$A$500)=$E$5))*(($E$6=0)+(YEAR('Daily Transactions'!$A$6:$A$500)=$E$6))*'Daily Transactions'!$F$6:$F$500) -> 0 | E19: =SUMPRODUCT(('Daily Transactions'!$B$6:$B$500=$B19)*('Daily Transactions'!$D$6:$D$500="Employee Salaries")*(($E$5=0)+(MONTH('Daily Transactions'!$A$6:$A$500)=$E$5))*(($E$6=0)+(YEAR('Daily Transactions'!$A$6:$A$500)=$E$6))*'Daily Transactions'!$F$6:$F$500) -> 0 | F19: =SUMPRODUCT(('Daily Transactions'!$B$6:$B$500=$B19)*('Daily Transactions'!$D$6:$D$500="KPLC")*(($E$5=0)+(MONTH('Daily Transactions'!$A$6:$A$500)=$E$5))*(($E$6=0)+(YEAR('Daily Transactions'!$A$6:$A$500)=$E$6))*'Daily Transactions'!$F$6:$F$500) -> 0 | G19: =SUMPRODUCT(('Daily Transactions'!$B$6:$B$500=$B19)*('Daily Transactions'!$D$6:$D$500="Wifi")*(($E$5=0)+(MONTH('Daily Transactions'!$A$6:$A$500)=$E$5))*(($E$6=0)+(YEAR('Daily Transactions'!$A$6:$A$500)=$E$6))*'Daily Transactions'!$F$6:$F$500) -> 0 | H19: =SUMPRODUCT(('Daily Transactions'!$B$6:$B$500=$B19)*('Daily Transactions'!$D$6:$D$500="Rent")*(($E$5=0)+(MONTH('Daily Transactions'!$A$6:$A$500)=$E$5))*(($E$6=0)+(YEAR('Daily Transactions'!$A$6:$A$500)=$E$6))*'Daily Transactions'!$F$6:$F$500) -> 0 | I19: =SUMPRODUCT(('Daily Transactions'!$B$6:$B$500=$B19)*('Daily Transactions'!$D$6:$D$500="Supplier Claims")*(($E$5=0)+(MONTH('Daily Transactions'!$A$6:$A$500)=$E$5))*(($E$6=0)+(YEAR('Daily Transactions'!$A$6:$A$500)=$E$6))*'Daily Transactions'!$F$6:$F$500) -> 0 | J19: =SUMPRODUCT(('Daily Transactions'!$B$6:$B$500=$B19)*('Daily Transactions'!$D$6:$D$500="Other Expense")*(($E$5=0)+(MONTH('Daily Transactions'!$A$6:$A$500)=$E$5))*(($E$6=0)+(YEAR('Daily Transactions'!$A$6:$A$500)=$E$6))*'Daily Transactions'!$F$6:$F$500) -> 0 | K19: =D19-SUM(E19:J19) -> 0
B20: Lytus | C20: Kabarak | D20: =SUMPRODUCT(('Daily Transactions'!$B$6:$B$500=$B20)*('Daily Transactions'!$C$6:$C$500="Income")*(($E$5=0)+(MONTH('Daily Transactions'!$A$6:$A$500)=$E$5))*(($E$6=0)+(YEAR('Daily Transactions'!$A$6:$A$500)=$E$6))*'Daily Transactions'!$F$6:$F$500) -> 0 | E20: =SUMPRODUCT(('Daily Transactions'!$B$6:$B$500=$B20)*('Daily Transactions'!$D$6:$D$500="Employee Salaries")*(($E$5=0)+(MONTH('Daily Transactions'!$A$6:$A$500)=$E$5))*(($E$6=0)+(YEAR('Daily Transactions'!$A$6:$A$500)=$E$6))*'Daily Transactions'!$F$6:$F$500) -> 0 | F20: =SUMPRODUCT(('Daily Transactions'!$B$6:$B$500=$B20)*('Daily Transactions'!$D$6:$D$500="KPLC")*(($E$5=0)+(MONTH('Daily Transactions'!$A$6:$A$500)=$E$5))*(($E$6=0)+(YEAR('Daily Transactions'!$A$6:$A$500)=$E$6))*'Daily Transactions'!$F$6:$F$500) -> 0 | G20: =SUMPRODUCT(('Daily Transactions'!$B$6:$B$500=$B20)*('Daily Transactions'!$D$6:$D$500="Wifi")*(($E$5=0)+(MONTH('Daily Transactions'!$A$6:$A$500)=$E$5))*(($E$6=0)+(YEAR('Daily Transactions'!$A$6:$A$500)=$E$6))*'Daily Transactions'!$F$6:$F$500) -> 0 | H20: =SUMPRODUCT(('Daily Transactions'!$B$6:$B$500=$B20)*('Daily Transactions'!$D$6:$D$500="Rent")*(($E$5=0)+(MONTH('Daily Transactions'!$A$6:$A$500)=$E$5))*(($E$6=0)+(YEAR('Daily Transactions'!$A$6:$A$500)=$E$6))*'Daily Transactions'!$F$6:$F$500) -> 0 | I20: =SUMPRODUCT(('Daily Transactions'!$B$6:$B$500=$B20)*('Daily Transactions'!$D$6:$D$500="Supplier Claims")*(($E$5=0)+(MONTH('Daily Transactions'!$A$6:$A$500)=$E$5))*(($E$6=0)+(YEAR('Daily Transactions'!$A$6:$A$500)=$E$6))*'Daily Transactions'!$F$6:$F$500) -> 0 | J20: =SUMPRODUCT(('Daily Transactions'!$B$6:$B$500=$B20)*('Daily Transactions'!$D$6:$D$500="Other Expense")*(($E$5=0)+(MONTH('Daily Transactions'!$A$6:$A$500)=$E$5))*(($E$6=0)+(YEAR('Daily Transactions'!$A$6:$A$500)=$E$6))*'Daily Transactions'!$F$6:$F$500) -> 0 | K20: =D20-SUM(E20:J20) -> 0
B21: BNB Milimani | C21: Milimani | D21: =SUMPRODUCT(('Daily Transactions'!$B$6:$B$500=$B21)*('Daily Transactions'!$C$6:$C$500="Income")*(($E$5=0)+(MONTH('Daily Transactions'!$A$6:$A$500)=$E$5))*(($E$6=0)+(YEAR('Daily Transactions'!$A$6:$A$500)=$E$6))*'Daily Transactions'!$F$6:$F$500) -> 0 | E21: =SUMPRODUCT(('Daily Transactions'!$B$6:$B$500=$B21)*('Daily Transactions'!$D$6:$D$500="Employee Salaries")*(($E$5=0)+(MONTH('Daily Transactions'!$A$6:$A$500)=$E$5))*(($E$6=0)+(YEAR('Daily Transactions'!$A$6:$A$500)=$E$6))*'Daily Transactions'!$F$6:$F$500) -> 0 | F21: =SUMPRODUCT(('Daily Transactions'!$B$6:$B$500=$B21)*('Daily Transactions'!$D$6:$D$500="KPLC")*(($E$5=0)+(MONTH('Daily Transactions'!$A$6:$A$500)=$E$5))*(($E$6=0)+(YEAR('Daily Transactions'!$A$6:$A$500)=$E$6))*'Daily Transactions'!$F$6:$F$500) -> 0 | G21: =SUMPRODUCT(('Daily Transactions'!$B$6:$B$500=$B21)*('Daily Transactions'!$D$6:$D$500="Wifi")*(($E$5=0)+(MONTH('Daily Transactions'!$A$6:$A$500)=$E$5))*(($E$6=0)+(YEAR('Daily Transactions'!$A$6:$A$500)=$E$6))*'Daily Transactions'!$F$6:$F$500) -> 0 | H21: =SUMPRODUCT(('Daily Transactions'!$B$6:$B$500=$B21)*('Daily Transactions'!$D$6:$D$500="Rent")*(($E$5=0)+(MONTH('Daily Transactions'!$A$6:$A$500)=$E$5))*(($E$6=0)+(YEAR('Daily Transactions'!$A$6:$A$500)=$E$6))*'Daily Transactions'!$F$6:$F$500) -> 0 | I21: =SUMPRODUCT(('Daily Transactions'!$B$6:$B$500=$B21)*('Daily Transactions'!$D$6:$D$500="Supplier Claims")*(($E$5=0)+(MONTH('Daily Transactions'!$A$6:$A$500)=$E$5))*(($E$6=0)+(YEAR('Daily Transactions'!$A$6:$A$500)=$E$6))*'Daily Transactions'!$F$6:$F$500) -> 0 | J21: =SUMPRODUCT(('Daily Transactions'!$B$6:$B$500=$B21)*('Daily Transactions'!$D$6:$D$500="Other Expense")*(($E$5=0)+(MONTH('Daily Transactions'!$A$6:$A$500)=$E$5))*(($E$6=0)+(YEAR('Daily Transactions'!$A$6:$A$500)=$E$6))*'Daily Transactions'!$F$6:$F$500) -> 0 | K21: =D21-SUM(E21:J21) -> 0
B22: BNB Kiamunyi | C22: Nakuru | D22: =SUMPRODUCT(('Daily Transactions'!$B$6:$B$500=$B22)*('Daily Transactions'!$C$6:$C$500="Income")*(($E$5=0)+(MONTH('Daily Transactions'!$A$6:$A$500)=$E$5))*(($E$6=0)+(YEAR('Daily Transactions'!$A$6:$A$500)=$E$6))*'Daily Transactions'!$F$6:$F$500) -> 0 | E22: =SUMPRODUCT(('Daily Transactions'!$B$6:$B$500=$B22)*('Daily Transactions'!$D$6:$D$500="Employee Salaries")*(($E$5=0)+(MONTH('Daily Transactions'!$A$6:$A$500)=$E$5))*(($E$6=0)+(YEAR('Daily Transactions'!$A$6:$A$500)=$E$6))*'Daily Transactions'!$F$6:$F$500) -> 0 | F22: =SUMPRODUCT(('Daily Transactions'!$B$6:$B$500=$B22)*('Daily Transactions'!$D$6:$D$500="KPLC")*(($E$5=0)+(MONTH('Daily Transactions'!$A$6:$A$500)=$E$5))*(($E$6=0)+(YEAR('Daily Transactions'!$A$6:$A$500)=$E$6))*'Daily Transactions'!$F$6:$F$500) -> 0 | G22: =SUMPRODUCT(('Daily Transactions'!$B$6:$B$500=$B22)*('Daily Transactions'!$D$6:$D$500="Wifi")*(($E$5=0)+(MONTH('Daily Transactions'!$A$6:$A$500)=$E$5))*(($E$6=0)+(YEAR('Daily Transactions'!$A$6:$A$500)=$E$6))*'Daily Transactions'!$F$6:$F$500) -> 0 | H22: =SUMPRODUCT(('Daily Transactions'!$B$6:$B$500=$B22)*('Daily Transactions'!$D$6:$D$500="Rent")*(($E$5=0)+(MONTH('Daily Transactions'!$A$6:$A$500)=$E$5))*(($E$6=0)+(YEAR('Daily Transactions'!$A$6:$A$500)=$E$6))*'Daily Transactions'!$F$6:$F$500) -> 0 | I22: =SUMPRODUCT(('Daily Transactions'!$B$6:$B$500=$B22)*('Daily Transactions'!$D$6:$D$500="Supplier Claims")*(($E$5=0)+(MONTH('Daily Transactions'!$A$6:$A$500)=$E$5))*(($E$6=0)+(YEAR('Daily Transactions'!$A$6:$A$500)=$E$6))*'Daily Transactions'!$F$6:$F$500) -> 0 | J22: =SUMPRODUCT(('Daily Transactions'!$B$6:$B$500=$B22)*('Daily Transactions'!$D$6:$D$500="Other Expense")*(($E$5=0)+(MONTH('Daily Transactions'!$A$6:$A$500)=$E$5))*(($E$6=0)+(YEAR('Daily Transactions'!$A$6:$A$500)=$E$6))*'Daily Transactions'!$F$6:$F$500) -> 0 | K22: =D22-SUM(E22:J22) -> 0
B23: NBO Warehouse | C23: Nairobi | D23: =SUMPRODUCT(('Daily Transactions'!$B$6:$B$500=$B23)*('Daily Transactions'!$C$6:$C$500="Income")*(($E$5=0)+(MONTH('Daily Transactions'!$A$6:$A$500)=$E$5))*(($E$6=0)+(YEAR('Daily Transactions'!$A$6:$A$500)=$E$6))*'Daily Transactions'!$F$6:$F$500) -> 0 | E23: =SUMPRODUCT(('Daily Transactions'!$B$6:$B$500=$B23)*('Daily Transactions'!$D$6:$D$500="Employee Salaries")*(($E$5=0)+(MONTH('Daily Transactions'!$A$6:$A$500)=$E$5))*(($E$6=0)+(YEAR('Daily Transactions'!$A$6:$A$500)=$E$6))*'Daily Transactions'!$F$6:$F$500) -> 0 | F23: =SUMPRODUCT(('Daily Transactions'!$B$6:$B$500=$B23)*('Daily Transactions'!$D$6:$D$500="KPLC")*(($E$5=0)+(MONTH('Daily Transactions'!$A$6:$A$500)=$E$5))*(($E$6=0)+(YEAR('Daily Transactions'!$A$6:$A$500)=$E$6))*'Daily Transactions'!$F$6:$F$500) -> 0 | G23: =SUMPRODUCT(('Daily Transactions'!$B$6:$B$500=$B23)*('Daily Transactions'!$D$6:$D$500="Wifi")*(($E$5=0)+(MONTH('Daily Transactions'!$A$6:$A$500)=$E$5))*(($E$6=0)+(YEAR('Daily Transactions'!$A$6:$A$500)=$E$6))*'Daily Transactions'!$F$6:$F$500) -> 0 | H23: =SUMPRODUCT(('Daily Transactions'!$B$6:$B$500=$B23)*('Daily Transactions'!$D$6:$D$500="Rent")*(($E$5=0)+(MONTH('Daily Transactions'!$A$6:$A$500)=$E$5))*(($E$6=0)+(YEAR('Daily Transactions'!$A$6:$A$500)=$E$6))*'Daily Transactions'!$F$6:$F$500) -> 0 | I23: =SUMPRODUCT(('Daily Transactions'!$B$6:$B$500=$B23)*('Daily Transactions'!$D$6:$D$500="Supplier Claims")*(($E$5=0)+(MONTH('Daily Transactions'!$A$6:$A$500)=$E$5))*(($E$6=0)+(YEAR('Daily Transactions'!$A$6:$A$500)=$E$6))*'Daily Transactions'!$F$6:$F$500) -> 0 | J23: =SUMPRODUCT(('Daily Transactions'!$B$6:$B$500=$B23)*('Daily Transactions'!$D$6:$D$500="Other Expense")*(($E$5=0)+(MONTH('Daily Transactions'!$A$6:$A$500)=$E$5))*(($E$6=0)+(YEAR('Daily Transactions'!$A$6:$A$500)=$E$6))*'Daily Transactions'!$F$6:$F$500) -> 0 | K23: =D23-SUM(E23:J23) -> 0
B24: TOTAL | D24: =SUM(D16:D23) -> 0 | E24: =SUM(E16:E23) -> 0 | F24: =SUM(F16:F23) -> 0 | G24: =SUM(G16:G23) -> 0 | H24: =SUM(H16:H23) -> 0 | I24: =SUM(I16:I23) -> 0 | J24: =SUM(J16:J23) -> 0 | K24: =SUM(K16:K23) -> 0
B46: Expense Category | C46: Total
B47: Employee Salaries | C47: =E24 -> 0
B48: KPLC | C48: =F24 -> 0
B49: Wifi | C49: =G24 -> 0
B50: Rent | C50: =H24 -> 0
B51: Supplier Claims | C51: =I24 -> 0
B52: Other Expense | C52: =J24 -> 0

Sheet Setup
B2: SETUP — Branches & Categories
B3: Used to populate dropdown lists on other sheets. Edit here to add/rename branches or categories.
P4: Employees (sub-categories of 'Employee Salaries')
B5: Branch | C5: Location | F5: Transaction Type | H5: Income Category | J5: Expense Category | L5: Payment Method | N5: Claim Status | P5: Employee Name | Q5: Branch | R5: Dropdown Value (auto)
B6: China Ndogo | C6: Nairobi | F6: Income | H6: Printing Jobs Revenue | J6: Employee Salaries | L6: Cash | N6: Pending | P6: Jane Wanjiru | Q6: China Ndogo | R6: =IF(P6="","",P6&" ("&Q6&")") -> Jane Wanjiru (China Ndogo)
B7: Yhe Cut | C7: Nakuru | F7: Expense | H7: Design Services | J7: KPLC | L7: M-Pesa | N7: Resolved | P7: Peter Otieno | Q7: China Ndogo | R7: =IF(P7="","",P7&" ("&Q7&")") -> Peter Otieno (China Ndogo)
B8: Heri Ads | C8: Eldoret | H8: Branding/Signage | J8: Wifi | L8: Bank Transfer | N8: Disputed | P8: Mary Chebet | Q8: Yhe Cut | R8: =IF(P8="","",P8&" ("&Q8&")") -> Mary Chebet (Yhe Cut)
B9: Brands Point | C9: Ravine | H9: Other Income | J9: Rent | L9: Cheque | P9: Samuel Kiptoo | Q9: Heri Ads | R9: =IF(P9="","",P9&" ("&Q9&")") -> Samuel Kiptoo (Heri Ads)
B10: Lytus | C10: Kabarak | J10: Supplier Claims | P10: Grace Naliaka | Q10: Brands Point | R10: =IF(P10="","",P10&" ("&Q10&")") -> Grace Naliaka (Brands Point)
B11: BNB Milimani | C11: Milimani | J11: Printing Materials | P11: David Mwangi | Q11: Lytus | R11: =IF(P11="","",P11&" ("&Q11&")") -> David Mwangi (Lytus)
B12: BNB Kiamunyi | C12: Nakuru | J12: Transport | P12: Alice Njeri | Q12: BNB Milimani | R12: =IF(P12="","",P12&" ("&Q12&")") -> Alice Njeri (BNB Milimani)
B13: NBO Warehouse | C13: Nairobi | J13: Repairs & Maintenance | R13: =IF(P13="","",P13&" ("&Q13&")")
J14: Other Expense | R14: =IF(P14="","",P14&" ("&Q14&")")
J15: ↳ Employee Salaries: see Employees table (right) for named sub-categories | R15: =IF(P15="","",P15&" ("&Q15&")")
R16: =IF(P16="","",P16&" ("&Q16&")")
R17: =IF(P17="","",P17&" ("&Q17&")")
R18: =IF(P18="","",P18&" ("&Q18&")")
R19: =IF(P19="","",P19&" ("&Q19&")")
R20: =IF(P20="","",P20&" ("&Q20&")")
R21: =IF(P21="","",P21&" ("&Q21&")")
R22: =IF(P22="","",P22&" ("&Q22&")")
R23: =IF(P23="","",P23&" ("&Q23&")")
R24: =IF(P24="","",P24&" ("&Q24&")")
R25: =IF(P25="","",P25&" ("&Q25&")")
R26: =IF(P26="","",P26&" ("&Q26&")")
R27: =IF(P27="","",P27&" ("&Q27&")")
... R55: =IF(P55="","",P55&" ("&Q55&")")

Sheet Daily Transactions
A1: DAILY ACCOUNTS — TRANSACTION LOG
A2: Log every income and expense entry here, one row per transaction. Dropdowns keep entries consistent.
F3: Running Total (Income - Expense): | H3: =SUMIFS(F6:F500,C6:C500,"Income")-SUMIFS(F6:F500,C6:C500,"Expense") -> 0
A5: Date | B5: Branch | C5: Type | D5: Category | E5: Description | F5: Amount (KES) | G5: Payment Method | H5: Notes | I5: Linked Bill (optional) | J5: Employee (if Salary) | K5: Linked Claim (if not billed)

Sheet Bills & Payments Due
A1: BILLS & PAYMENTS DUE TRACKER
A2: Add each bill once here. When you log the payment in Daily Transactions, pick its 'Linked Bill' from the dropdown — Amount Paid, Balance and Status below update automatically.
A4: Alert window (days before due to flag 'Due Soon'): | E4: 5 | G4: Overdue: | H4: =COUNTIFS(L7:L500,"Overdue")+COUNTIFS(L7:L500,"Partially Paid - Overdue") -> 12 | I4: Due Soon: | J4: =COUNTIFS(L7:L500,"Due Soon")+COUNTIFS(L7:L500,"Due Today") -> 2 | K4: Partially Paid: | L4: =COUNTIFS(L7:L500,"Partially Paid")+COUNTIFS(L7:L500,"Partially Paid - Due Today")+COUNTIFS(L7:L500,"Partially Paid - Overdue") -> 0
A6: Bill ID | B6: Bill / Payment | C6: Branch | D6: Category | E6: Amount (KES) | F6: Due Date | G6: Recurring? | H6: Frequency | I6: Amount Paid | J6: Balance Remaining | K6: Days Until Due | L6: Status | M6: Paid Date | N6: Notes | O6: Match Key (auto - do not edit) | P6: Employee (if Salary)
A7: BILL-001 | B7: shop rent | C7: Yhe Cut | D7: Rent | E7: KES 105,000 | F7: 46215 | G7: Yes | H7: Monthly | I7: KES 0 | J7: KES 105,000 | K7: -5 | L7: Overdue | O7: BILL-001 | shop rent (Yhe Cut)
A8: BILL-002 | B8: Internet | C8: Yhe Cut | D8: Wifi | E8: KES 5,000 | F8: 46208 | G8: Yes | H8: Monthly | I8: KES 0 | J8: KES 5,000 | K8: -12 | L8: Overdue | O8: BILL-002 | Internet (Yhe Cut)
A9: BILL-003 | B9: shop rent | C9: China Ndogo | D9: Rent | E9: KES 25,000 | F9: 46218 | G9: Yes | H9: Monthly | I9: KES 0 | J9: KES 25,000 | K9: -2 | L9: Overdue | O9: BILL-003 | shop rent (China Ndogo)
A10: BILL-004 | B10: Internet | C10: China Ndogo | D10: Wifi | E10: KES 3,000 | F10: 46222 | G10: Yes | H10: Monthly | I10: KES 0 | J10: KES 3,000 | K10: 2 | L10: Due Soon | O10: BILL-004 | Internet (China Ndogo)
A11: BILL-005 | B11: warehouse rent | C11: NBO Warehouse | D11: Rent | E11: KES 60,000 | F11: 46215 | G11: Yes | H11: Monthly | I11: KES 0 | J11: KES 60,000 | K11: -5 | L11: Overdue | O11: BILL-005 | warehouse rent (NBO Warehouse)
A12: BILL-006 | B12: Internet | C12: NBO Warehouse | D12: Wifi | E12: KES 5,000 | F12: 46209 | G12: Yes | H12: Monthly | I12: KES 0 | J12: KES 5,000 | K12: -11 | L12: Overdue | O12: BILL-006 | Internet (NBO Warehouse)
A13: BILL-007 | B13: shop rent | C13: Lytus | D13: Rent | E13: KES 4,500 | F13: 46211 | G13: Yes | H13: Monthly | I13: KES 0 | J13: KES 4,500 | K13: -9 | L13: Overdue | O13: BILL-007 | shop rent (Lytus)
A14: BILL-008 | B14: Internet | C14: Lytus | D14: Wifi | E14: KES 3,000 | F14: 46219 | G14: Yes | H14: Monthly | I14: KES 0 | J14: KES 3,000 | K14: -1 | L14: Overdue | O14: BILL-008 | Internet (Lytus)
A15: BILL-009 | B15: shop rent | C15: Brands Point | D15: Rent | E15: KES 6,000 | F15: 46212 | G15: Yes | H15: Monthly | I15: KES 0 | J15: KES 6,000 | K15: -8 | L15: Overdue | O15: BILL-009 | shop rent (Brands Point)
A16: BILL-010 | B16: Internet | C16: Brands Point | D16: Wifi | E16: KES 3,000 | F16: 46218 | G16: Yes | H16: Monthly | I16: KES 0 | J16: KES 3,000 | K16: -2 | L16: Overdue | O16: BILL-010 | Internet (Brands Point)
A17: BILL-011 | B17: shop rent | C17: Heri Ads | D17: Rent | E17: KES 22,500 | F17: 46225 | G17: Yes | H17: Monthly | I17: KES 0 | J17: KES 22,500 | K17: 5 | L17: Due Soon | O17: BILL-011 | shop rent (Heri Ads)
A18: BILL-012 | B18: Internet | C18: Heri Ads | D18: Wifi | E18: KES 3,000 | F18: 46218 | G18: Yes | H18: Monthly | I18: KES 0 | J18: KES 3,000 | K18: -2 | L18: Overdue | O18: BILL-012 | Internet (Heri Ads)
A19: BILL-013 | B19: bnb fee | C19: BNB Milimani | D19: Rent | E19: KES 22,500 | G19: Yes | H19: Monthly | I19: KES 0 | J19: KES 22,500 | L19: Upcoming | O19: BILL-013 | bnb fee (BNB Milimani)
A20: BILL-014 | B20: Internet | C20: BNB Milimani | D20: Wifi | E20: KES 3,000 | G20: Yes | H20: Monthly | I20: KES 0 | J20: KES 3,000 | L20: Upcoming | O20: BILL-014 | Internet (BNB Milimani)
A21: BILL-015 | B21: bnb fee | C21: BNB Kiamunyi | D21: Rent | E21: KES 48,000 | F21: 46215 | G21: Yes | H21: Monthly | I21: KES 0 | J21: KES 48,000 | K21: -5 | L21: Overdue | O21: BILL-015 | bnb fee (BNB Kiamunyi)
A22: BILL-016 | B22: Internet | C22: BNB Kiamunyi | D22: Wifi | E22: KES 12,000 | F22: 46219 | G22: Yes | H22: Monthly | I22: KES 0 | J22: KES 12,000 | K22: -1 | L22: Overdue | O22: BILL-016 | Internet (BNB Kiamunyi)
A23: =IF(B23="","","BILL-"&TEXT(ROW()-6,"000")) | I23: =IF($A23="",0,SUMIFS('Daily Transactions'!$F$6:$F$500,'Daily Transactions'!$I$6:$I$500,$O23,'Daily Transactions'!$C$6:$C$500,"Expense")) -> 0 | J23: =IF($A23="","",MAX(0,E23-I23)) | K23: =IF(F23="","",F23-TODAY()) | L23: =IF($A23="","",IF(I23>=E23,"Paid in Full",IF(I23>0,IF(K23<0,"Partially Paid - Overdue",IF(K23<=0,"Partially Paid - Due Today","Partially Paid")),IF(K23<0,"Overdue",IF(K23=0,"Due Today",IF(K23<=$E$4,"Due Soon","Upcoming")))))) | M23: =IF($A23="","",IF(I23>=E23,MAXIFS('Daily Transactions'!$A$6:$A$500,'Daily Transactions'!$I$6:$I$500,$O23,'Daily Transactions'!$C$6:$C$500,"Expense"),"")) | O23: =IF(B23="","",$A23&" | "&B23&" ("&C23&")")
A24: =IF(B24="","","BILL-"&TEXT(ROW()-6,"000")) | I24: =IF($A24="",0,SUMIFS('Daily Transactions'!$F$6:$F$500,'Daily Transactions'!$I$6:$I$500,$O24,'Daily Transactions'!$C$6:$C$500,"Expense")) -> 0 | J24: =IF($A24="","",MAX(0,E24-I24)) | K24: =IF(F24="","",F24-TODAY()) | L24: =IF($A24="","",IF(I24>=E24,"Paid in Full",IF(I24>0,IF(K24<0,"Partially Paid - Overdue",IF(K24<=0,"Partially Paid - Due Today","Partially Paid")),IF(K24<0,"Overdue",IF(K24=0,"Due Today",IF(K24<=$E$4,"Due Soon","Upcoming")))))) | M24: =IF($A24="","",IF(I24>=E24,MAXIFS('Daily Transactions'!$A$6:$A$500,'Daily Transactions'!$I$6:$I$500,$O24,'Daily Transactions'!$C$6:$C$500,"Expense"),"")) | O24: =IF(B24="","",$A24&" | "&B24&" ("&C24&")")
A25: =IF(B25="","","BILL-"&TEXT(ROW()-6,"000")) | I25: =IF($A25="",0,SUMIFS('Daily Transactions'!$F$6:$F$500,'Daily Transactions'!$I$6:$I$500,$O25,'Daily Transactions'!$C$6:$C$500,"Expense")) -> 0 | J25: =IF($A25="","",MAX(0,E25-I25)) | K25: =IF(F25="","",F25-TODAY()) | L25: =IF($A25="","",IF(I25>=E25,"Paid in Full",IF(I25>0,IF(K25<0,"Partially Paid - Overdue",IF(K25<=0,"Partially Paid - Due Today","Partially Paid")),IF(K25<0,"Overdue",IF(K25=0,"Due Today",IF(K25<=$E$4,"Due Soon","Upcoming")))))) | M25: =IF($A25="","",IF(I25>=E25,MAXIFS('Daily Transactions'!$A$6:$A$500,'Daily Transactions'!$I$6:$I$500,$O25,'Daily Transactions'!$C$6:$C$500,"Expense"),"")) | O25: =IF(B25="","",$A25&" | "&B25&" ("&C25&")")
A26: =IF(B26="","","BILL-"&TEXT(ROW()-6,"000")) | I26: =IF($A26="",0,SUMIFS('Daily Transactions'!$F$6:$F$500,'Daily Transactions'!$I$6:$I$500,$O26,'Daily Transactions'!$C$6:$C$500,"Expense")) -> 0 | J26: =IF($A26="","",MAX(0,E26-I26)) | K26: =IF(F26="","",F26-TODAY()) | L26: =IF($A26="","",IF(I26>=E26,"Paid in Full",IF(I26>0,IF(K26<0,"Partially Paid - Overdue",IF(K26<=0,"Partially Paid - Due Today","Partially Paid")),IF(K26<0,"Overdue",IF(K26=0,"Due Today",IF(K26<=$E$4,"Due Soon","Upcoming")))))) | M26: =IF($A26="","",IF(I26>=E26,MAXIFS('Daily Transactions'!$A$6:$A$500,'Daily Transactions'!$I$6:$I$500,$O26,'Daily Transactions'!$C$6:$C$500,"Expense"),"")) | O26: =IF(B26="","",$A26&" | "&B26&" ("&C26&")")
A27: =IF(B27="","","BILL-"&TEXT(ROW()-6,"000")) | I27: =IF($A27="",0,SUMIFS('Daily Transactions'!$F$6:$F$500,'Daily Transactions'!$I$6:$I$500,$O27,'Daily Transactions'!$C$6:$C$500,"Expense")) -> 0 | J27: =IF($A27="","",MAX(0,E27-I27)) | K27: =IF(F27="","",F27-TODAY()) | L27: =IF($A27="","",IF(I27>=E27,"Paid in Full",IF(I27>0,IF(K27<0,"Partially Paid - Overdue",IF(K27<=0,"Partially Paid - Due Today","Partially Paid")),IF(K27<0,"Overdue",IF(K27=0,"Due Today",IF(K27<=$E$4,"Due Soon","Upcoming")))))) | M27: =IF($A27="","",IF(I27>=E27,MAXIFS('Daily Transactions'!$A$6:$A$500,'Daily Transactions'!$I$6:$I$500,$O27,'Daily Transactions'!$C$6:$C$500,"Expense"),"")) | O27: =IF(B27="","",$A27&" | "&B27&" ("&C27&")")
A28: =IF(B28="","","BILL-"&TEXT(ROW()-6,"000")) | I28: =IF($A28="",0,SUMIFS('Daily Transactions'!$F$6:$F$500,'Daily Transactions'!$I$6:$I$500,$O28,'Daily Transactions'!$C$6:$C$500,"Expense")) -> 0 | J28: =IF($A28="","",MAX(0,E28-I28)) | K28: =IF(F28="","",F28-TODAY()) | L28: =IF($A28="","",IF(I28>=E28,"Paid in Full",IF(I28>0,IF(K28<0,"Partially Paid - Overdue",IF(K28<=0,"Partially Paid - Due Today","Partially Paid")),IF(K28<0,"Overdue",IF(K28=0,"Due Today",IF(K28<=$E$4,"Due Soon","Upcoming")))))) | M28: =IF($A28="","",IF(I28>=E28,MAXIFS('Daily Transactions'!$A$6:$A$500,'Daily Transactions'!$I$6:$I$500,$O28,'Daily Transactions'!$C$6:$C$500,"Expense"),"")) | O28: =IF(B28="","",$A28&" | "&B28&" ("&C28&")")
A29: =IF(B29="","","BILL-"&TEXT(ROW()-6,"000")) | I29: =IF($A29="",0,SUMIFS('Daily Transactions'!$F$6:$F$500,'Daily Transactions'!$I$6:$I$500,$O29,'Daily Transactions'!$C$6:$C$500,"Expense")) -> 0 | J29: =IF($A29="","",MAX(0,E29-I29)) | K29: =IF(F29="","",F29-TODAY()) | L29: =IF($A29="","",IF(I29>=E29,"Paid in Full",IF(I29>0,IF(K29<0,"Partially Paid - Overdue",IF(K29<=0,"Partially Paid - Due Today","Partially Paid")),IF(K29<0,"Overdue",IF(K29=0,"Due Today",IF(K29<=$E$4,"Due Soon","Upcoming")))))) | M29: =IF($A29="","",IF(I29>=E29,MAXIFS('Daily Transactions'!$A$6:$A$500,'Daily Transactions'!$I$6:$I$500,$O29,'Daily Transactions'!$C$6:$C$500,"Expense"),"")) | O29: =IF(B29="","",$A29&" | "&B29&" ("&C29&")")
A30: =IF(B30="","","BILL-"&TEXT(ROW()-6,"000")) | I30: =IF($A30="",0,SUMIFS('Daily Transactions'!$F$6:$F$500,'Daily Transactions'!$I$6:$I$500,$O30,'Daily Transactions'!$C$6:$C$500,"Expense")) -> 0 | J30: =IF($A30="","",MAX(0,E30-I30)) | K30: =IF(F30="","",F30-TODAY()) | L30: =IF($A30="","",IF(I30>=E30,"Paid in Full",IF(I30>0,IF(K30<0,"Partially Paid - Overdue",IF(K30<=0,"Partially Paid - Due Today","Partially Paid")),IF(K30<0,"Overdue",IF(K30=0,"Due Today",IF(K30<=$E$4,"Due Soon","Upcoming")))))) | M30: =IF($A30="","",IF(I30>=E30,MAXIFS('Daily Transactions'!$A$6:$A$500,'Daily Transactions'!$I$6:$I$500,$O30,'Daily Transactions'!$C$6:$C$500,"Expense"),"")) | O30: =IF(B30="","",$A30&" | "&B30&" ("&C30&")")
A31: =IF(B31="","","BILL-"&TEXT(ROW()-6,"000")) | I31: =IF($A31="",0,SUMIFS('Daily Transactions'!$F$6:$F$500,'Daily Transactions'!$I$6:$I$500,$O31,'Daily Transactions'!$C$6:$C$500,"Expense")) -> 0 | J31: =IF($A31="","",MAX(0,E31-I31)) | K31: =IF(F31="","",F31-TODAY()) | L31: =IF($A31="","",IF(I31>=E31,"Paid in Full",IF(I31>0,IF(K31<0,"Partially Paid - Overdue",IF(K31<=0,"Partially Paid - Due Today","Partially Paid")),IF(K31<0,"Overdue",IF(K31=0,"Due Today",IF(K31<=$E$4,"Due Soon","Upcoming")))))) | M31: =IF($A31="","",IF(I31>=E31,MAXIFS('Daily Transactions'!$A$6:$A$500,'Daily Transactions'!$I$6:$I$500,$O31,'Daily Transactions'!$C$6:$C$500,"Expense"),"")) | O31: =IF(B31="","",$A31&" | "&B31&" ("&C31&")")
A32: =IF(B32="","","BILL-"&TEXT(ROW()-6,"000")) | I32: =IF($A32="",0,SUMIFS('Daily Transactions'!$F$6:$F$500,'Daily Transactions'!$I$6:$I$500,$O32,'Daily Transactions'!$C$6:$C$500,"Expense")) -> 0 | J32: =IF($A32="","",MAX(0,E32-I32)) | K32: =IF(F32="","",F32-TODAY()) | L32: =IF($A32="","",IF(I32>=E32,"Paid in Full",IF(I32>0,IF(K32<0,"Partially Paid - Overdue",IF(K32<=0,"Partially Paid - Due Today","Partially Paid")),IF(K32<0,"Overdue",IF(K32=0,"Due Today",IF(K32<=$E$4,"Due Soon","Upcoming")))))) | M32: =IF($A32="","",IF(I32>=E32,MAXIFS('Daily Transactions'!$A$6:$A$500,'Daily Transactions'!$I$6:$I$500,$O32,'Daily Transactions'!$C$6:$C$500,"Expense"),"")) | O32: =IF(B32="","",$A32&" | "&B32&" ("&C32&")")
A33: =IF(B33="","","BILL-"&TEXT(ROW()-6,"000")) | I33: =IF($A33="",0,SUMIFS('Daily Transactions'!$F$6:$F$500,'Daily Transactions'!$I$6:$I$500,$O33,'Daily Transactions'!$C$6:$C$500,"Expense")) -> 0 | J33: =IF($A33="","",MAX(0,E33-I33)) | K33: =IF(F33="","",F33-TODAY()) | L33: =IF($A33="","",IF(I33>=E33,"Paid in Full",IF(I33>0,IF(K33<0,"Partially Paid - Overdue",IF(K33<=0,"Partially Paid - Due Today","Partially Paid")),IF(K33<0,"Overdue",IF(K33=0,"Due Today",IF(K33<=$E$4,"Due Soon","Upcoming")))))) | M33: =IF($A33="","",IF(I33>=E33,MAXIFS('Daily Transactions'!$A$6:$A$500,'Daily Transactions'!$I$6:$I$500,$O33,'Daily Transactions'!$C$6:$C$500,"Expense"),"")) | O33: =IF(B33="","",$A33&" | "&B33&" ("&C33&")")
A34: =IF(B34="","","BILL-"&TEXT(ROW()-6,"000")) | I34: =IF($A34="",0,SUMIFS('Daily Transactions'!$F$6:$F$500,'Daily Transactions'!$I$6:$I$500,$O34,'Daily Transactions'!$C$6:$C$500,"Expense")) -> 0 | J34: =IF($A34="","",MAX(0,E34-I34)) | K34: =IF(F34="","",F34-TODAY()) | L34: =IF($A34="","",IF(I34>=E34,"Paid in Full",IF(I34>0,IF(K34<0,"Partially Paid - Overdue",IF(K34<=0,"Partially Paid - Due Today","Partially Paid")),IF(K34<0,"Overdue",IF(K34=0,"Due Today",IF(K34<=$E$4,"Due Soon","Upcoming")))))) | M34: =IF($A34="","",IF(I34>=E34,MAXIFS('Daily Transactions'!$A$6:$A$500,'Daily Transactions'!$I$6:$I$500,$O34,'Daily Transactions'!$C$6:$C$500,"Expense"),"")) | O34: =IF(B34="","",$A34&" | "&B34&" ("&C34&")")
... A500: =IF(B500="","","BILL-"&TEXT(ROW()-6,"000")) | I500: =IF($A500="",0,SUMIFS('Daily Transactions'!$F$6:$F$500,'Daily Transactions'!$I$6:$I$500,$O500,'Daily Transactions'!$C$6:$C$500,"Expense")) -> 0 | J500: =IF($A500="","",MAX(0,E500-I500)) | K500: =IF(F500="","",F500-TODAY()) | L500: =IF($A500="","",IF(I500>=E500,"Paid in Full",IF(I500>0,IF(K500<0,"Partially Paid - Overdue",IF(K500<=0,"Partially Paid - Due Today","Partially Paid")),IF(K500<0,"Overdue",IF(K500=0,"Due Today",IF(K500<=$E$4,"Due Soon","Upcoming")))))) | M500: =IF($A500="","",IF(I500>=E500,MAXIFS('Daily Transactions'!$A$6:$A$500,'Daily Transactions'!$I$6:$I$500,$O500,'Daily Transactions'!$C$6:$C$500,"Expense"),"")) | O500: =IF(B500="","",$A500&" | "&B500&" ("&C500&")")

Sheet Branch Summary
B2: MONTHLY BRANCH SUMMARY
B3: Select a branch and year; monthly totals pull automatically from Daily Transactions.
B5: Branch: | C5: China Ndogo | E5: Year: | F5: 2026
B7: Category | C7: Jan | D7: Feb | E7: Mar | F7: Apr | G7: May | H7: Jun | I7: Jul | J7: Aug | K7: Sep | L7: Oct | M7: Nov | N7: Dec | O7: Total
B8: Income | C8: =SUMIFS('Daily Transactions'!$F$6:$F$500,'Daily Transactions'!$B$6:$B$500,$C$5,'Daily Transactions'!$C$6:$C$500,"Income",'Daily Transactions'!$A$6:$A$500,">="&DATE($F$5,1,1),'Daily Transactions'!$A$6:$A$500,"<"&EDATE(DATE($F$5,1,1),1)) -> 0 | D8: =SUMIFS('Daily Transactions'!$F$6:$F$500,'Daily Transactions'!$B$6:$B$500,$C$5,'Daily Transactions'!$C$6:$C$500,"Income",'Daily Transactions'!$A$6:$A$500,">="&DATE($F$5,2,1),'Daily Transactions'!$A$6:$A$500,"<"&EDATE(DATE($F$5,2,1),1)) -> 0 | E8: =SUMIFS('Daily Transactions'!$F$6:$F$500,'Daily Transactions'!$B$6:$B$500,$C$5,'Daily Transactions'!$C$6:$C$500,"Income",'Daily Transactions'!$A$6:$A$500,">="&DATE($F$5,3,1),'Daily Transactions'!$A$6:$A$500,"<"&EDATE(DATE($F$5,3,1),1)) -> 0 | F8: =SUMIFS('Daily Transactions'!$F$6:$F$500,'Daily Transactions'!$B$6:$B$500,$C$5,'Daily Transactions'!$C$6:$C$500,"Income",'Daily Transactions'!$A$6:$A$500,">="&DATE($F$5,4,1),'Daily Transactions'!$A$6:$A$500,"<"&EDATE(DATE($F$5,4,1),1)) -> 0 | G8: =SUMIFS('Daily Transactions'!$F$6:$F$500,'Daily Transactions'!$B$6:$B$500,$C$5,'Daily Transactions'!$C$6:$C$500,"Income",'Daily Transactions'!$A$6:$A$500,">="&DATE($F$5,5,1),'Daily Transactions'!$A$6:$A$500,"<"&EDATE(DATE($F$5,5,1),1)) -> 0 | H8: =SUMIFS('Daily Transactions'!$F$6:$F$500,'Daily Transactions'!$B$6:$B$500,$C$5,'Daily Transactions'!$C$6:$C$500,"Income",'Daily Transactions'!$A$6:$A$500,">="&DATE($F$5,6,1),'Daily Transactions'!$A$6:$A$500,"<"&EDATE(DATE($F$5,6,1),1)) -> 0 | I8: =SUMIFS('Daily Transactions'!$F$6:$F$500,'Daily Transactions'!$B$6:$B$500,$C$5,'Daily Transactions'!$C$6:$C$500,"Income",'Daily Transactions'!$A$6:$A$500,">="&DATE($F$5,7,1),'Daily Transactions'!$A$6:$A$500,"<"&EDATE(DATE($F$5,7,1),1)) -> 0 | J8: =SUMIFS('Daily Transactions'!$F$6:$F$500,'Daily Transactions'!$B$6:$B$500,$C$5,'Daily Transactions'!$C$6:$C$500,"Income",'Daily Transactions'!$A$6:$A$500,">="&DATE($F$5,8,1),'Daily Transactions'!$A$6:$A$500,"<"&EDATE(DATE($F$5,8,1),1)) -> 0 | K8: =SUMIFS('Daily Transactions'!$F$6:$F$500,'Daily Transactions'!$B$6:$B$500,$C$5,'Daily Transactions'!$C$6:$C$500,"Income",'Daily Transactions'!$A$6:$A$500,">="&DATE($F$5,9,1),'Daily Transactions'!$A$6:$A$500,"<"&EDATE(DATE($F$5,9,1),1)) -> 0 | L8: =SUMIFS('Daily Transactions'!$F$6:$F$500,'Daily Transactions'!$B$6:$B$500,$C$5,'Daily Transactions'!$C$6:$C$500,"Income",'Daily Transactions'!$A$6:$A$500,">="&DATE($F$5,10,1),'Daily Transactions'!$A$6:$A$500,"<"&EDATE(DATE($F$5,10,1),1)) -> 0 | M8: =SUMIFS('Daily Transactions'!$F$6:$F$500,'Daily Transactions'!$B$6:$B$500,$C$5,'Daily Transactions'!$C$6:$C$500,"Income",'Daily Transactions'!$A$6:$A$500,">="&DATE($F$5,11,1),'Daily Transactions'!$A$6:$A$500,"<"&EDATE(DATE($F$5,11,1),1)) -> 0 | N8: =SUMIFS('Daily Transactions'!$F$6:$F$500,'Daily Transactions'!$B$6:$B$500,$C$5,'Daily Transactions'!$C$6:$C$500,"Income",'Daily Transactions'!$A$6:$A$500,">="&DATE($F$5,12,1),'Daily Transactions'!$A$6:$A$500,"<"&EDATE(DATE($F$5,12,1),1)) -> 0 | O8: =SUM(C8:N8) -> 0
B9: Exp: Employee Salaries | C9: =SUMIFS('Daily Transactions'!$F$6:$F$500,'Daily Transactions'!$B$6:$B$500,$C$5,'Daily Transactions'!$C$6:$C$500,"Expense",'Daily Transactions'!$D$6:$D$500,"Employee Salaries",'Daily Transactions'!$A$6:$A$500,">="&DATE($F$5,1,1),'Daily Transactions'!$A$6:$A$500,"<"&EDATE(DATE($F$5,1,1),1)) -> 0 | D9: =SUMIFS('Daily Transactions'!$F$6:$F$500,'Daily Transactions'!$B$6:$B$500,$C$5,'Daily Transactions'!$C$6:$C$500,"Expense",'Daily Transactions'!$D$6:$D$500,"Employee Salaries",'Daily Transactions'!$A$6:$A$500,">="&DATE($F$5,2,1),'Daily Transactions'!$A$6:$A$500,"<"&EDATE(DATE($F$5,2,1),1)) -> 0 | E9: =SUMIFS('Daily Transactions'!$F$6:$F$500,'Daily Transactions'!$B$6:$B$500,$C$5,'Daily Transactions'!$C$6:$C$500,"Expense",'Daily Transactions'!$D$6:$D$500,"Employee Salaries",'Daily Transactions'!$A$6:$A$500,">="&DATE($F$5,3,1),'Daily Transactions'!$A$6:$A$500,"<"&EDATE(DATE($F$5,3,1),1)) -> 0 | F9: =SUMIFS('Daily Transactions'!$F$6:$F$500,'Daily Transactions'!$B$6:$B$500,$C$5,'Daily Transactions'!$C$6:$C$500,"Expense",'Daily Transactions'!$D$6:$D$500,"Employee Salaries",'Daily Transactions'!$A$6:$A$500,">="&DATE($F$5,4,1),'Daily Transactions'!$A$6:$A$500,"<"&EDATE(DATE($F$5,4,1),1)) -> 0 | G9: =SUMIFS('Daily Transactions'!$F$6:$F$500,'Daily Transactions'!$B$6:$B$500,$C$5,'Daily Transactions'!$C$6:$C$500,"Expense",'Daily Transactions'!$D$6:$D$500,"Employee Salaries",'Daily Transactions'!$A$6:$A$500,">="&DATE($F$5,5,1),'Daily Transactions'!$A$6:$A$500,"<"&EDATE(DATE($F$5,5,1),1)) -> 0 | H9: =SUMIFS('Daily Transactions'!$F$6:$F$500,'Daily Transactions'!$B$6:$B$500,$C$5,'Daily Transactions'!$C$6:$C$500,"Expense",'Daily Transactions'!$D$6:$D$500,"Employee Salaries",'Daily Transactions'!$A$6:$A$500,">="&DATE($F$5,6,1),'Daily Transactions'!$A$6:$A$500,"<"&EDATE(DATE($F$5,6,1),1)) -> 0 | I9: =SUMIFS('Daily Transactions'!$F$6:$F$500,'Daily Transactions'!$B$6:$B$500,$C$5,'Daily Transactions'!$C$6:$C$500,"Expense",'Daily Transactions'!$D$6:$D$500,"Employee Salaries",'Daily Transactions'!$A$6:$A$500,">="&DATE($F$5,7,1),'Daily Transactions'!$A$6:$A$500,"<"&EDATE(DATE($F$5,7,1),1)) -> 0 | J9: =SUMIFS('Daily Transactions'!$F$6:$F$500,'Daily Transactions'!$B$6:$B$500,$C$5,'Daily Transactions'!$C$6:$C$500,"Expense",'Daily Transactions'!$D$6:$D$500,"Employee Salaries",'Daily Transactions'!$A$6:$A$500,">="&DATE($F$5,8,1),'Daily Transactions'!$A$6:$A$500,"<"&EDATE(DATE($F$5,8,1),1)) -> 0 | K9: =SUMIFS('Daily Transactions'!$F$6:$F$500,'Daily Transactions'!$B$6:$B$500,$C$5,'Daily Transactions'!$C$6:$C$500,"Expense",'Daily Transactions'!$D$6:$D$500,"Employee Salaries",'Daily Transactions'!$A$6:$A$500,">="&DATE($F$5,9,1),'Daily Transactions'!$A$6:$A$500,"<"&EDATE(DATE($F$5,9,1),1)) -> 0 | L9: =SUMIFS('Daily Transactions'!$F$6:$F$500,'Daily Transactions'!$B$6:$B$500,$C$5,'Daily Transactions'!$C$6:$C$500,"Expense",'Daily Transactions'!$D$6:$D$500,"Employee Salaries",'Daily Transactions'!$A$6:$A$500,">="&DATE($F$5,10,1),'Daily Transactions'!$A$6:$A$500,"<"&EDATE(DATE($F$5,10,1),1)) -> 0 | M9: =SUMIFS('Daily Transactions'!$F$6:$F$500,'Daily Transactions'!$B$6:$B$500,$C$5,'Daily Transactions'!$C$6:$C$500,"Expense",'Daily Transactions'!$D$6:$D$500,"Employee Salaries",'Daily Transactions'!$A$6:$A$500,">="&DATE($F$5,11,1),'Daily Transactions'!$A$6:$A$500,"<"&EDATE(DATE($F$5,11,1),1)) -> 0 | N9: =SUMIFS('Daily Transactions'!$F$6:$F$500,'Daily Transactions'!$B$6:$B$500,$C$5,'Daily Transactions'!$C$6:$C$500,"Expense",'Daily Transactions'!$D$6:$D$500,"Employee Salaries",'Daily Transactions'!$A$6:$A$500,">="&DATE($F$5,12,1),'Daily Transactions'!$A$6:$A$500,"<"&EDATE(DATE($F$5,12,1),1)) -> 0 | O9: =SUM(C9:N9) -> 0
B10: Exp: KPLC | C10: =SUMIFS('Daily Transactions'!$F$6:$F$500,'Daily Transactions'!$B$6:$B$500,$C$5,'Daily Transactions'!$C$6:$C$500,"Expense",'Daily Transactions'!$D$6:$D$500,"KPLC",'Daily Transactions'!$A$6:$A$500,">="&DATE($F$5,1,1),'Daily Transactions'!$A$6:$A$500,"<"&EDATE(DATE($F$5,1,1),1)) -> 0 | D10: =SUMIFS('Daily Transactions'!$F$6:$F$500,'Daily Transactions'!$B$6:$B$500,$C$5,'Daily Transactions'!$C$6:$C$500,"Expense",'Daily Transactions'!$D$6:$D$500,"KPLC",'Daily Transactions'!$A$6:$A$500,">="&DATE($F$5,2,1),'Daily Transactions'!$A$6:$A$500,"<"&EDATE(DATE($F$5,2,1),1)) -> 0 | E10: =SUMIFS('Daily Transactions'!$F$6:$F$500,'Daily Transactions'!$B$6:$B$500,$C$5,'Daily Transactions'!$C$6:$C$500,"Expense",'Daily Transactions'!$D$6:$D$500,"KPLC",'Daily Transactions'!$A$6:$A$500,">="&DATE($F$5,3,1),'Daily Transactions'!$A$6:$A$500,"<"&EDATE(DATE($F$5,3,1),1)) -> 0 | F10: =SUMIFS('Daily Transactions'!$F$6:$F$500,'Daily Transactions'!$B$6:$B$500,$C$5,'Daily Transactions'!$C$6:$C$500,"Expense",'Daily Transactions'!$D$6:$D$500,"KPLC",'Daily Transactions'!$A$6:$A$500,">="&DATE($F$5,4,1),'Daily Transactions'!$A$6:$A$500,"<"&EDATE(DATE($F$5,4,1),1)) -> 0 | G10: =SUMIFS('Daily Transactions'!$F$6:$F$500,'Daily Transactions'!$B$6:$B$500,$C$5,'Daily Transactions'!$C$6:$C$500,"Expense",'Daily Transactions'!$D$6:$D$500,"KPLC",'Daily Transactions'!$A$6:$A$500,">="&DATE($F$5,5,1),'Daily Transactions'!$A$6:$A$500,"<"&EDATE(DATE($F$5,5,1),1)) -> 0 | H10: =SUMIFS('Daily Transactions'!$F$6:$F$500,'Daily Transactions'!$B$6:$B$500,$C$5,'Daily Transactions'!$C$6:$C$500,"Expense",'Daily Transactions'!$D$6:$D$500,"KPLC",'Daily Transactions'!$A$6:$A$500,">="&DATE($F$5,6,1),'Daily Transactions'!$A$6:$A$500,"<"&EDATE(DATE($F$5,6,1),1)) -> 0 | I10: =SUMIFS('Daily Transactions'!$F$6:$F$500,'Daily Transactions'!$B$6:$B$500,$C$5,'Daily Transactions'!$C$6:$C$500,"Expense",'Daily Transactions'!$D$6:$D$500,"KPLC",'Daily Transactions'!$A$6:$A$500,">="&DATE($F$5,7,1),'Daily Transactions'!$A$6:$A$500,"<"&EDATE(DATE($F$5,7,1),1)) -> 0 | J10: =SUMIFS('Daily Transactions'!$F$6:$F$500,'Daily Transactions'!$B$6:$B$500,$C$5,'Daily Transactions'!$C$6:$C$500,"Expense",'Daily Transactions'!$D$6:$D$500,"KPLC",'Daily Transactions'!$A$6:$A$500,">="&DATE($F$5,8,1),'Daily Transactions'!$A$6:$A$500,"<"&EDATE(DATE($F$5,8,1),1)) -> 0 | K10: =SUMIFS('Daily Transactions'!$F$6:$F$500,'Daily Transactions'!$B$6:$B$500,$C$5,'Daily Transactions'!$C$6:$C$500,"Expense",'Daily Transactions'!$D$6:$D$500,"KPLC",'Daily Transactions'!$A$6:$A$500,">="&DATE($F$5,9,1),'Daily Transactions'!$A$6:$A$500,"<"&EDATE(DATE($F$5,9,1),1)) -> 0 | L10: =SUMIFS('Daily Transactions'!$F$6:$F$500,'Daily Transactions'!$B$6:$B$500,$C$5,'Daily Transactions'!$C$6:$C$500,"Expense",'Daily Transactions'!$D$6:$D$500,"KPLC",'Daily Transactions'!$A$6:$A$500,">="&DATE($F$5,10,1),'Daily Transactions'!$A$6:$A$500,"<"&EDATE(DATE($F$5,10,1),1)) -> 0 | M10: =SUMIFS('Daily Transactions'!$F$6:$F$500,'Daily Transactions'!$B$6:$B$500,$C$5,'Daily Transactions'!$C$6:$C$500,"Expense",'Daily Transactions'!$D$6:$D$500,"KPLC",'Daily Transactions'!$A$6:$A$500,">="&DATE($F$5,11,1),'Daily Transactions'!$A$6:$A$500,"<"&EDATE(DATE($F$5,11,1),1)) -> 0 | N10: =SUMIFS('Daily Transactions'!$F$6:$F$500,'Daily Transactions'!$B$6:$B$500,$C$5,'Daily Transactions'!$C$6:$C$500,"Expense",'Daily Transactions'!$D$6:$D$500,"KPLC",'Daily Transactions'!$A$6:$A$500,">="&DATE($F$5,12,1),'Daily Transactions'!$A$6:$A$500,"<"&EDATE(DATE($F$5,12,1),1)) -> 0 | O10: =SUM(C10:N10) -> 0
B11: Exp: Wifi | C11: =SUMIFS('Daily Transactions'!$F$6:$F$500,'Daily Transactions'!$B$6:$B$500,$C$5,'Daily Transactions'!$C$6:$C$500,"Expense",'Daily Transactions'!$D$6:$D$500,"Wifi",'Daily Transactions'!$A$6:$A$500,">="&DATE($F$5,1,1),'Daily Transactions'!$A$6:$A$500,"<"&EDATE(DATE($F$5,1,1),1)) -> 0 | D11: =SUMIFS('Daily Transactions'!$F$6:$F$500,'Daily Transactions'!$B$6:$B$500,$C$5,'Daily Transactions'!$C$6:$C$500,"Expense",'Daily Transactions'!$D$6:$D$500,"Wifi",'Daily Transactions'!$A$6:$A$500,">="&DATE($F$5,2,1),'Daily Transactions'!$A$6:$A$500,"<"&EDATE(DATE($F$5,2,1),1)) -> 0 | E11: =SUMIFS('Daily Transactions'!$F$6:$F$500,'Daily Transactions'!$B$6:$B$500,$C$5,'Daily Transactions'!$C$6:$C$500,"Expense",'Daily Transactions'!$D$6:$D$500,"Wifi",'Daily Transactions'!$A$6:$A$500,">="&DATE($F$5,3,1),'Daily Transactions'!$A$6:$A$500,"<"&EDATE(DATE($F$5,3,1),1)) -> 0 | F11: =SUMIFS('Daily Transactions'!$F$6:$F$500,'Daily Transactions'!$B$6:$B$500,$C$5,'Daily Transactions'!$C$6:$C$500,"Expense",'Daily Transactions'!$D$6:$D$500,"Wifi",'Daily Transactions'!$A$6:$A$500,">="&DATE($F$5,4,1),'Daily Transactions'!$A$6:$A$500,"<"&EDATE(DATE($F$5,4,1),1)) -> 0 | G11: =SUMIFS('Daily Transactions'!$F$6:$F$500,'Daily Transactions'!$B$6:$B$500,$C$5,'Daily Transactions'!$C$6:$C$500,"Expense",'Daily Transactions'!$D$6:$D$500,"Wifi",'Daily Transactions'!$A$6:$A$500,">="&DATE($F$5,5,1),'Daily Transactions'!$A$6:$A$500,"<"&EDATE(DATE($F$5,5,1),1)) -> 0 | H11: =SUMIFS('Daily Transactions'!$F$6:$F$500,'Daily Transactions'!$B$6:$B$500,$C$5,'Daily Transactions'!$C$6:$C$500,"Expense",'Daily Transactions'!$D$6:$D$500,"Wifi",'Daily Transactions'!$A$6:$A$500,">="&DATE($F$5,6,1),'Daily Transactions'!$A$6:$A$500,"<"&EDATE(DATE($F$5,6,1),1)) -> 0 | I11: =SUMIFS('Daily Transactions'!$F$6:$F$500,'Daily Transactions'!$B$6:$B$500,$C$5,'Daily Transactions'!$C$6:$C$500,"Expense",'Daily Transactions'!$D$6:$D$500,"Wifi",'Daily Transactions'!$A$6:$A$500,">="&DATE($F$5,7,1),'Daily Transactions'!$A$6:$A$500,"<"&EDATE(DATE($F$5,7,1),1)) -> 0 | J11: =SUMIFS('Daily Transactions'!$F$6:$F$500,'Daily Transactions'!$B$6:$B$500,$C$5,'Daily Transactions'!$C$6:$C$500,"Expense",'Daily Transactions'!$D$6:$D$500,"Wifi",'Daily Transactions'!$A$6:$A$500,">="&DATE($F$5,8,1),'Daily Transactions'!$A$6:$A$500,"<"&EDATE(DATE($F$5,8,1),1)) -> 0 | K11: =SUMIFS('Daily Transactions'!$F$6:$F$500,'Daily Transactions'!$B$6:$B$500,$C$5,'Daily Transactions'!$C$6:$C$500,"Expense",'Daily Transactions'!$D$6:$D$500,"Wifi",'Daily Transactions'!$A$6:$A$500,">="&DATE($F$5,9,1),'Daily Transactions'!$A$6:$A$500,"<"&EDATE(DATE($F$5,9,1),1)) -> 0 | L11: =SUMIFS('Daily Transactions'!$F$6:$F$500,'Daily Transactions'!$B$6:$B$500,$C$5,'Daily Transactions'!$C$6:$C$500,"Expense",'Daily Transactions'!$D$6:$D$500,"Wifi",'Daily Transactions'!$A$6:$A$500,">="&DATE($F$5,10,1),'Daily Transactions'!$A$6:$A$500,"<"&EDATE(DATE($F$5,10,1),1)) -> 0 | M11: =SUMIFS('Daily Transactions'!$F$6:$F$500,'Daily Transactions'!$B$6:$B$500,$C$5,'Daily Transactions'!$C$6:$C$500,"Expense",'Daily Transactions'!$D$6:$D$500,"Wifi",'Daily Transactions'!$A$6:$A$500,">="&DATE($F$5,11,1),'Daily Transactions'!$A$6:$A$500,"<"&EDATE(DATE($F$5,11,1),1)) -> 0 | N11: =SUMIFS('Daily Transactions'!$F$6:$F$500,'Daily Transactions'!$B$6:$B$500,$C$5,'Daily Transactions'!$C$6:$C$500,"Expense",'Daily Transactions'!$D$6:$D$500,"Wifi",'Daily Transactions'!$A$6:$A$500,">="&DATE($F$5,12,1),'Daily Transactions'!$A$6:$A$500,"<"&EDATE(DATE($F$5,12,1),1)) -> 0 | O11: =SUM(C11:N11) -> 0
B12: Exp: Rent | C12: =SUMIFS('Daily Transactions'!$F$6:$F$500,'Daily Transactions'!$B$6:$B$500,$C$5,'Daily Transactions'!$C$6:$C$500,"Expense",'Daily Transactions'!$D$6:$D$500,"Rent",'Daily Transactions'!$A$6:$A$500,">="&DATE($F$5,1,1),'Daily Transactions'!$A$6:$A$500,"<"&EDATE(DATE($F$5,1,1),1)) -> 0 | D12: =SUMIFS('Daily Transactions'!$F$6:$F$500,'Daily Transactions'!$B$6:$B$500,$C$5,'Daily Transactions'!$C$6:$C$500,"Expense",'Daily Transactions'!$D$6:$D$500,"Rent",'Daily Transactions'!$A$6:$A$500,">="&DATE($F$5,2,1),'Daily Transactions'!$A$6:$A$500,"<"&EDATE(DATE($F$5,2,1),1)) -> 0 | E12: =SUMIFS('Daily Transactions'!$F$6:$F$500,'Daily Transactions'!$B$6:$B$500,$C$5,'Daily Transactions'!$C$6:$C$500,"Expense",'Daily Transactions'!$D$6:$D$500,"Rent",'Daily Transactions'!$A$6:$A$500,">="&DATE($F$5,3,1),'Daily Transactions'!$A$6:$A$500,"<"&EDATE(DATE($F$5,3,1),1)) -> 0 | F12: =SUMIFS('Daily Transactions'!$F$6:$F$500,'Daily Transactions'!$B$6:$B$500,$C$5,'Daily Transactions'!$C$6:$C$500,"Expense",'Daily Transactions'!$D$6:$D$500,"Rent",'Daily Transactions'!$A$6:$A$500,">="&DATE($F$5,4,1),'Daily Transactions'!$A$6:$A$500,"<"&EDATE(DATE($F$5,4,1),1)) -> 0 | G12: =SUMIFS('Daily Transactions'!$F$6:$F$500,'Daily Transactions'!$B$6:$B$500,$C$5,'Daily Transactions'!$C$6:$C$500,"Expense",'Daily Transactions'!$D$6:$D$500,"Rent",'Daily Transactions'!$A$6:$A$500,">="&DATE($F$5,5,1),'Daily Transactions'!$A$6:$A$500,"<"&EDATE(DATE($F$5,5,1),1)) -> 0 | H12: =SUMIFS('Daily Transactions'!$F$6:$F$500,'Daily Transactions'!$B$6:$B$500,$C$5,'Daily Transactions'!$C$6:$C$500,"Expense",'Daily Transactions'!$D$6:$D$500,"Rent",'Daily Transactions'!$A$6:$A$500,">="&DATE($F$5,6,1),'Daily Transactions'!$A$6:$A$500,"<"&EDATE(DATE($F$5,6,1),1)) -> 0 | I12: =SUMIFS('Daily Transactions'!$F$6:$F$500,'Daily Transactions'!$B$6:$B$500,$C$5,'Daily Transactions'!$C$6:$C$500,"Expense",'Daily Transactions'!$D$6:$D$500,"Rent",'Daily Transactions'!$A$6:$A$500,">="&DATE($F$5,7,1),'Daily Transactions'!$A$6:$A$500,"<"&EDATE(DATE($F$5,7,1),1)) -> 0 | J12: =SUMIFS('Daily Transactions'!$F$6:$F$500,'Daily Transactions'!$B$6:$B$500,$C$5,'Daily Transactions'!$C$6:$C$500,"Expense",'Daily Transactions'!$D$6:$D$500,"Rent",'Daily Transactions'!$A$6:$A$500,">="&DATE($F$5,8,1),'Daily Transactions'!$A$6:$A$500,"<"&EDATE(DATE($F$5,8,1),1)) -> 0 | K12: =SUMIFS('Daily Transactions'!$F$6:$F$500,'Daily Transactions'!$B$6:$B$500,$C$5,'Daily Transactions'!$C$6:$C$500,"Expense",'Daily Transactions'!$D$6:$D$500,"Rent",'Daily Transactions'!$A$6:$A$500,">="&DATE($F$5,9,1),'Daily Transactions'!$A$6:$A$500,"<"&EDATE(DATE($F$5,9,1),1)) -> 0 | L12: =SUMIFS('Daily Transactions'!$F$6:$F$500,'Daily Transactions'!$B$6:$B$500,$C$5,'Daily Transactions'!$C$6:$C$500,"Expense",'Daily Transactions'!$D$6:$D$500,"Rent",'Daily Transactions'!$A$6:$A$500,">="&DATE($F$5,10,1),'Daily Transactions'!$A$6:$A$500,"<"&EDATE(DATE($F$5,10,1),1)) -> 0 | M12: =SUMIFS('Daily Transactions'!$F$6:$F$500,'Daily Transactions'!$B$6:$B$500,$C$5,'Daily Transactions'!$C$6:$C$500,"Expense",'Daily Transactions'!$D$6:$D$500,"Rent",'Daily Transactions'!$A$6:$A$500,">="&DATE($F$5,11,1),'Daily Transactions'!$A$6:$A$500,"<"&EDATE(DATE($F$5,11,1),1)) -> 0 | N12: =SUMIFS('Daily Transactions'!$F$6:$F$500,'Daily Transactions'!$B$6:$B$500,$C$5,'Daily Transactions'!$C$6:$C$500,"Expense",'Daily Transactions'!$D$6:$D$500,"Rent",'Daily Transactions'!$A$6:$A$500,">="&DATE($F$5,12,1),'Daily Transactions'!$A$6:$A$500,"<"&EDATE(DATE($F$5,12,1),1)) -> 0 | O12: =SUM(C12:N12) -> 0
B13: Exp: Supplier Claims | C13: =SUMIFS('Daily Transactions'!$F$6:$F$500,'Daily Transactions'!$B$6:$B$500,$C$5,'Daily Transactions'!$C$6:$C$500,"Expense",'Daily Transactions'!$D$6:$D$500,"Supplier Claims",'Daily Transactions'!$A$6:$A$500,">="&DATE($F$5,1,1),'Daily Transactions'!$A$6:$A$500,"<"&EDATE(DATE($F$5,1,1),1)) -> 0 | D13: =SUMIFS('Daily Transactions'!$F$6:$F$500,'Daily Transactions'!$B$6:$B$500,$C$5,'Daily Transactions'!$C$6:$C$500,"Expense",'Daily Transactions'!$D$6:$D$500,"Supplier Claims",'Daily Transactions'!$A$6:$A$500,">="&DATE($F$5,2,1),'Daily Transactions'!$A$6:$A$500,"<"&EDATE(DATE($F$5,2,1),1)) -> 0 | E13: =SUMIFS('Daily Transactions'!$F$6:$F$500,'Daily Transactions'!$B$6:$B$500,$C$5,'Daily Transactions'!$C$6:$C$500,"Expense",'Daily Transactions'!$D$6:$D$500,"Supplier Claims",'Daily Transactions'!$A$6:$A$500,">="&DATE($F$5,3,1),'Daily Transactions'!$A$6:$A$500,"<"&EDATE(DATE($F$5,3,1),1)) -> 0 | F13: =SUMIFS('Daily Transactions'!$F$6:$F$500,'Daily Transactions'!$B$6:$B$500,$C$5,'Daily Transactions'!$C$6:$C$500,"Expense",'Daily Transactions'!$D$6:$D$500,"Supplier Claims",'Daily Transactions'!$A$6:$A$500,">="&DATE($F$5,4,1),'Daily Transactions'!$A$6:$A$500,"<"&EDATE(DATE($F$5,4,1),1)) -> 0 | G13: =SUMIFS('Daily Transactions'!$F$6:$F$500,'Daily Transactions'!$B$6:$B$500,$C$5,'Daily Transactions'!$C$6:$C$500,"Expense",'Daily Transactions'!$D$6:$D$500,"Supplier Claims",'Daily Transactions'!$A$6:$A$500,">="&DATE($F$5,5,1),'Daily Transactions'!$A$6:$A$500,"<"&EDATE(DATE($F$5,5,1),1)) -> 0 | H13: =SUMIFS('Daily Transactions'!$F$6:$F$500,'Daily Transactions'!$B$6:$B$500,$C$5,'Daily Transactions'!$C$6:$C$500,"Expense",'Daily Transactions'!$D$6:$D$500,"Supplier Claims",'Daily Transactions'!$A$6:$A$500,">="&DATE($F$5,6,1),'Daily Transactions'!$A$6:$A$500,"<"&EDATE(DATE($F$5,6,1),1)) -> 0 | I13: =SUMIFS('Daily Transactions'!$F$6:$F$500,'Daily Transactions'!$B$6:$B$500,$C$5,'Daily Transactions'!$C$6:$C$500,"Expense",'Daily Transactions'!$D$6:$D$500,"Supplier Claims",'Daily Transactions'!$A$6:$A$500,">="&DATE($F$5,7,1),'Daily Transactions'!$A$6:$A$500,"<"&EDATE(DATE($F$5,7,1),1)) -> 0 | J13: =SUMIFS('Daily Transactions'!$F$6:$F$500,'Daily Transactions'!$B$6:$B$500,$C$5,'Daily Transactions'!$C$6:$C$500,"Expense",'Daily Transactions'!$D$6:$D$500,"Supplier Claims",'Daily Transactions'!$A$6:$A$500,">="&DATE($F$5,8,1),'Daily Transactions'!$A$6:$A$500,"<"&EDATE(DATE($F$5,8,1),1)) -> 0 | K13: =SUMIFS('Daily Transactions'!$F$6:$F$500,'Daily Transactions'!$B$6:$B$500,$C$5,'Daily Transactions'!$C$6:$C$500,"Expense",'Daily Transactions'!$D$6:$D$500,"Supplier Claims",'Daily Transactions'!$A$6:$A$500,">="&DATE($F$5,9,1),'Daily Transactions'!$A$6:$A$500,"<"&EDATE(DATE($F$5,9,1),1)) -> 0 | L13: =SUMIFS('Daily Transactions'!$F$6:$F$500,'Daily Transactions'!$B$6:$B$500,$C$5,'Daily Transactions'!$C$6:$C$500,"Expense",'Daily Transactions'!$D$6:$D$500,"Supplier Claims",'Daily Transactions'!$A$6:$A$500,">="&DATE($F$5,10,1),'Daily Transactions'!$A$6:$A$500,"<"&EDATE(DATE($F$5,10,1),1)) -> 0 | M13: =SUMIFS('Daily Transactions'!$F$6:$F$500,'Daily Transactions'!$B$6:$B$500,$C$5,'Daily Transactions'!$C$6:$C$500,"Expense",'Daily Transactions'!$D$6:$D$500,"Supplier Claims",'Daily Transactions'!$A$6:$A$500,">="&DATE($F$5,11,1),'Daily Transactions'!$A$6:$A$500,"<"&EDATE(DATE($F$5,11,1),1)) -> 0 | N13: =SUMIFS('Daily Transactions'!$F$6:$F$500,'Daily Transactions'!$B$6:$B$500,$C$5,'Daily Transactions'!$C$6:$C$500,"Expense",'Daily Transactions'!$D$6:$D$500,"Supplier Claims",'Daily Transactions'!$A$6:$A$500,">="&DATE($F$5,12,1),'Daily Transactions'!$A$6:$A$500,"<"&EDATE(DATE($F$5,12,1),1)) -> 0 | O13: =SUM(C13:N13) -> 0
B14: Exp: Printing Materials | C14: =SUMIFS('Daily Transactions'!$F$6:$F$500,'Daily Transactions'!$B$6:$B$500,$C$5,'Daily Transactions'!$C$6:$C$500,"Expense",'Daily Transactions'!$D$6:$D$500,"Printing Materials",'Daily Transactions'!$A$6:$A$500,">="&DATE($F$5,1,1),'Daily Transactions'!$A$6:$A$500,"<"&EDATE(DATE($F$5,1,1),1)) -> 0 | D14: =SUMIFS('Daily Transactions'!$F$6:$F$500,'Daily Transactions'!$B$6:$B$500,$C$5,'Daily Transactions'!$C$6:$C$500,"Expense",'Daily Transactions'!$D$6:$D$500,"Printing Materials",'Daily Transactions'!$A$6:$A$500,">="&DATE($F$5,2,1),'Daily Transactions'!$A$6:$A$500,"<"&EDATE(DATE($F$5,2,1),1)) -> 0 | E14: =SUMIFS('Daily Transactions'!$F$6:$F$500,'Daily Transactions'!$B$6:$B$500,$C$5,'Daily Transactions'!$C$6:$C$500,"Expense",'Daily Transactions'!$D$6:$D$500,"Printing Materials",'Daily Transactions'!$A$6:$A$500,">="&DATE($F$5,3,1),'Daily Transactions'!$A$6:$A$500,"<"&EDATE(DATE($F$5,3,1),1)) -> 0 | F14: =SUMIFS('Daily Transactions'!$F$6:$F$500,'Daily Transactions'!$B$6:$B$500,$C$5,'Daily Transactions'!$C$6:$C$500,"Expense",'Daily Transactions'!$D$6:$D$500,"Printing Materials",'Daily Transactions'!$A$6:$A$500,">="&DATE($F$5,4,1),'Daily Transactions'!$A$6:$A$500,"<"&EDATE(DATE($F$5,4,1),1)) -> 0 | G14: =SUMIFS('Daily Transactions'!$F$6:$F$500,'Daily Transactions'!$B$6:$B$500,$C$5,'Daily Transactions'!$C$6:$C$500,"Expense",'Daily Transactions'!$D$6:$D$500,"Printing Materials",'Daily Transactions'!$A$6:$A$500,">="&DATE($F$5,5,1),'Daily Transactions'!$A$6:$A$500,"<"&EDATE(DATE($F$5,5,1),1)) -> 0 | H14: =SUMIFS('Daily Transactions'!$F$6:$F$500,'Daily Transactions'!$B$6:$B$500,$C$5,'Daily Transactions'!$C$6:$C$500,"Expense",'Daily Transactions'!$D$6:$D$500,"Printing Materials",'Daily Transactions'!$A$6:$A$500,">="&DATE($F$5,6,1),'Daily Transactions'!$A$6:$A$500,"<"&EDATE(DATE($F$5,6,1),1)) -> 0 | I14: =SUMIFS('Daily Transactions'!$F$6:$F$500,'Daily Transactions'!$B$6:$B$500,$C$5,'Daily Transactions'!$C$6:$C$500,"Expense",'Daily Transactions'!$D$6:$D$500,"Printing Materials",'Daily Transactions'!$A$6:$A$500,">="&DATE($F$5,7,1),'Daily Transactions'!$A$6:$A$500,"<"&EDATE(DATE($F$5,7,1),1)) -> 0 | J14: =SUMIFS('Daily Transactions'!$F$6:$F$500,'Daily Transactions'!$B$6:$B$500,$C$5,'Daily Transactions'!$C$6:$C$500,"Expense",'Daily Transactions'!$D$6:$D$500,"Printing Materials",'Daily Transactions'!$A$6:$A$500,">="&DATE($F$5,8,1),'Daily Transactions'!$A$6:$A$500,"<"&EDATE(DATE($F$5,8,1),1)) -> 0 | K14: =SUMIFS('Daily Transactions'!$F$6:$F$500,'Daily Transactions'!$B$6:$B$500,$C$5,'Daily Transactions'!$C$6:$C$500,"Expense",'Daily Transactions'!$D$6:$D$500,"Printing Materials",'Daily Transactions'!$A$6:$A$500,">="&DATE($F$5,9,1),'Daily Transactions'!$A$6:$A$500,"<"&EDATE(DATE($F$5,9,1),1)) -> 0 | L14: =SUMIFS('Daily Transactions'!$F$6:$F$500,'Daily Transactions'!$B$6:$B$500,$C$5,'Daily Transactions'!$C$6:$C$500,"Expense",'Daily Transactions'!$D$6:$D$500,"Printing Materials",'Daily Transactions'!$A$6:$A$500,">="&DATE($F$5,10,1),'Daily Transactions'!$A$6:$A$500,"<"&EDATE(DATE($F$5,10,1),1)) -> 0 | M14: =SUMIFS('Daily Transactions'!$F$6:$F$500,'Daily Transactions'!$B$6:$B$500,$C$5,'Daily Transactions'!$C$6:$C$500,"Expense",'Daily Transactions'!$D$6:$D$500,"Printing Materials",'Daily Transactions'!$A$6:$A$500,">="&DATE($F$5,11,1),'Daily Transactions'!$A$6:$A$500,"<"&EDATE(DATE($F$5,11,1),1)) -> 0 | N14: =SUMIFS('Daily Transactions'!$F$6:$F$500,'Daily Transactions'!$B$6:$B$500,$C$5,'Daily Transactions'!$C$6:$C$500,"Expense",'Daily Transactions'!$D$6:$D$500,"Printing Materials",'Daily Transactions'!$A$6:$A$500,">="&DATE($F$5,12,1),'Daily Transactions'!$A$6:$A$500,"<"&EDATE(DATE($F$5,12,1),1)) -> 0 | O14: =SUM(C14:N14) -> 0
